{
	"registryname": "concretemixer",
    "localizedname": "Concrete Mixer",
	
    "parts": [
        {
            "x": -1,
            "y": 0,
            "z": 0,
            "nbt": {"casingColor":"16730368","id":"minecraft:tilecolorablemachinecomponent"},
            "elements": [
                "modularmachinery:blockcasing@0"
            ]
        },
        {
            "x": 2,
            "y": 4,
            "z": 2,
            "nbt": {"id":"immersiveengineering:ieslab","slabType":"0"},
            "elements": [
                "immersiveengineering:sheetmetal_slab@8"
            ]
        },
        {
            "x": -2,
            "y": 0,
            "z": 0,
            "elements": [
                "immersiveengineering:storage@8"
            ]
        },
        {
            "x": 2,
            "y": 2,
            "z": 1,
            "nbt": {"casingColor":"16730368","id":"minecraft:tilecolorablemachinecomponent"},
            "elements": [
                "modularmachinery:blockcasing@0"
            ]
        },
        {
            "x": 1,
            "y": 0,
            "z": 0,
            "nbt": {"casingColor":"16730368","id":"minecraft:tilecolorablemachinecomponent"},
            "elements": [
                "modularmachinery:blockcasing@0"
            ]
        },
        {
            "x": -3,
            "y": 0,
            "z": 0,
            "nbt": {"casingColor":"16730368","id":"minecraft:tilecolorablemachinecomponent"},
            "elements": [
                "modularmachinery:blockcasing@0"
            ]
        },
        {
            "x": 2,
            "y": 0,
            "z": 0,
            "elements": [
                "immersiveengineering:storage@8"
            ]
        },
        {
            "x": -4,
            "y": 0,
            "z": 0,
            "elements": [
                "immersiveengineering:storage@8"
            ]
        },
        {
            "x": 3,
            "y": 0,
            "z": 0,
            "nbt": {"casingColor":"16730368","id":"minecraft:tilecolorablemachinecomponent"},
            "elements": [
                "modularmachinery:blockcasing@0"
            ]
        },
        {
            "x": 4,
            "y": 0,
            "z": 0,
            "nbt": {"casingColor":"16730368","id":"minecraft:tilecolorablemachinecomponent"},
            "elements": [
                "modularmachinery:blockcasing@0"
            ]
        },
        {
            "x": 5,
            "y": 0,
            "z": 0,
            "elements": [
                "immersiveengineering:storage@8"
            ]
        },
        {
            "x": 5,
            "y": -1,
            "z": 0,
            "elements": [
                "immersiveengineering:storage@8"
            ]
        },
        {
            "x": 4,
            "y": -1,
            "z": 0,
            "nbt": {"casingColor":"16730368","id":"minecraft:tilecolorablemachinecomponent"},
            "elements": [
                "modularmachinery:blockcasing@0"
            ]
        },
        {
            "x": 3,
            "y": -1,
            "z": 0,
            "nbt": {"casingColor":"16730368","id":"minecraft:tilecolorablemachinecomponent"},
            "elements": [
                "modularmachinery:blockcasing@0"
            ]
        },
        {
            "x": -4,
            "y": 1,
            "z": 0,
            "nbt": {"id":"immersiveengineering:ieslab","slabType":"0"},
            "elements": [
                "immersiveengineering:sheetmetal_slab@8"
            ]
        },
        {
            "x": -3,
            "y": 1,
            "z": 0,
            "nbt": {"id":"immersiveengineering:ieslab","slabType":"0"},
            "elements": [
                "immersiveengineering:sheetmetal_slab@8"
            ]
        },
        {
            "x": -2,
            "y": 3,
            "z": 1,
            "nbt": {"conveyorBeltSubtypeNBT":{"dyeColour":"-1","direction":"0"},"facing":"3","conveyorBeltSubtype":"immersiveengineering:conveyor","id":"immersiveengineering:conveyorbelt"},
            "elements": [
                "immersiveengineering:conveyor@0"
            ]
        },
        {
            "x": 2,
            "y": -1,
            "z": 0,
            "elements": [
                "immersiveengineering:storage@8"
            ]
        },
        {
            "x": -2,
            "y": 1,
            "z": 0,
            "elements": [
                "immersiveengineering:storage@8"
            ]
        },
        {
            "x": 1,
            "y": -1,
            "z": 0,
            "nbt": {"casingColor":"16730368","id":"minecraft:tilecolorablemachinecomponent"},
            "elements": [
                "modularmachinery:blockcasing@0"
            ]
        },
        {
            "x": 0,
            "y": -1,
            "z": 0,
            "nbt": {"casingColor":"16730368","id":"minecraft:tilecolorablemachinecomponent"},
            "elements": [
                "modularmachinery:blockcasing@0"
            ]
        },
        {
            "x": 0,
            "y": 3,
            "z": 1,
            "elements": [
                "immersiveengineering:metal_decoration0@4"
            ]
        },
        {
            "x": -1,
            "y": 1,
            "z": 0,
            "nbt": {"casingColor":"16730368","id":"minecraft:tilecolorablemachinecomponent"},
            "elements": [
                "modularmachinery:blockcasing@0"
            ]
        },
        {
            "x": 0,
            "y": 1,
            "z": 0,
            "nbt": {"casingColor":"16730368","id":"minecraft:tilecolorablemachinecomponent"},
            "elements": [
                "modularmachinery:blockcasing@0"
            ]
        },
        {
            "x": -1,
            "y": -1,
            "z": 0,
            "nbt": {"casingColor":"16730368","id":"minecraft:tilecolorablemachinecomponent"},
            "elements": [
                "modularmachinery:blockcasing@0"
            ]
        },
        {
            "x": -2,
            "y": -1,
            "z": 0,
            "elements": [
                "immersiveengineering:storage@8"
            ]
        },
        {
            "x": 2,
            "y": 3,
            "z": 1,
            "nbt": {"conveyorBeltSubtypeNBT":{"dyeColour":"-1","direction":"0"},"facing":"2","conveyorBeltSubtype":"immersiveengineering:conveyor","id":"immersiveengineering:conveyorbelt"},
            "elements": [
                "immersiveengineering:conveyor@0"
            ]
        },
        {
            "x": 1,
            "y": 1,
            "z": 0,
            "nbt": {"casingColor":"16730368","id":"minecraft:tilecolorablemachinecomponent"},
            "elements": [
                "modularmachinery:blockcasing@0"
            ]
        },
        {
            "x": -3,
            "y": -1,
            "z": 0,
            "nbt": {"casingColor":"16730368","id":"minecraft:tilecolorablemachinecomponent"},
            "elements": [
                "modularmachinery:blockcasing@0"
            ]
        },
        {
            "x": 2,
            "y": 1,
            "z": 0,
            "elements": [
                "immersiveengineering:storage@8"
            ]
        },
        {
            "x": -4,
            "y": -1,
            "z": 0,
            "elements": [
                "immersiveengineering:storage@8"
            ]
        },
        {
            "x": 3,
            "y": 1,
            "z": 0,
            "nbt": {"id":"immersiveengineering:ieslab","slabType":"0"},
            "elements": [
                "immersiveengineering:sheetmetal_slab@8"
            ]
        },
        {
            "x": 4,
            "y": 1,
            "z": 0,
            "nbt": {"id":"immersiveengineering:ieslab","slabType":"0"},
            "elements": [
                "immersiveengineering:sheetmetal_slab@8"
            ]
        },
        {
            "x": 5,
            "y": 1,
            "z": 0,
            "nbt": {"id":"immersiveengineering:ieslab","slabType":"0"},
            "elements": [
                "immersiveengineering:sheetmetal_slab@8"
            ]
        },
        {
            "x": -2,
            "y": 4,
            "z": 1,
            "nbt": {"id":"immersiveengineering:ieslab","slabType":"0"},
            "elements": [
                "immersiveengineering:sheetmetal_slab@8"
            ]
        },
        {
            "x": -2,
            "y": 2,
            "z": 0,
            "elements": [
                "immersiveengineering:storage@8"
            ]
        },
        {
            "x": -1,
            "y": 4,
            "z": 1,
            "nbt": {"id":"immersiveengineering:ieslab","slabType":"0"},
            "elements": [
                "immersiveengineering:sheetmetal_slab@8"
            ]
        },
        {
            "x": 0,
            "y": 4,
            "z": 1,
            "nbt": {"id":"immersiveengineering:ieslab","slabType":"0"},
            "elements": [
                "immersiveengineering:sheetmetal_slab@8"
            ]
        },
        {
            "x": -1,
            "y": 2,
            "z": 0,
            "elements": [
                "minecraft:glass@0"
            ]
        },
        {
            "x": 1,
            "y": 4,
            "z": 1,
            "nbt": {"id":"immersiveengineering:ieslab","slabType":"0"},
            "elements": [
                "immersiveengineering:sheetmetal_slab@8"
            ]
        },
        {
            "x": 0,
            "y": 2,
            "z": 0,
            "elements": [
                "minecraft:glass@0"
            ]
        },
        {
            "x": 2,
            "y": 4,
            "z": 1,
            "nbt": {"id":"immersiveengineering:ieslab","slabType":"0"},
            "elements": [
                "immersiveengineering:sheetmetal_slab@8"
            ]
        },
        {
            "x": 1,
            "y": 2,
            "z": 0,
            "elements": [
                "minecraft:glass@0"
            ]
        },
        {
            "x": 2,
            "y": 2,
            "z": 0,
            "elements": [
                "immersiveengineering:storage@8"
            ]
        },
        {
            "x": -2,
            "y": 3,
            "z": 0,
            "elements": [
                "immersiveengineering:storage@8"
            ]
        },
        {
            "x": -1,
            "y": 3,
            "z": 0,
            "elements": [
                "immersiveengineering:storage@8"
            ]
        },
        {
            "x": 0,
            "y": 3,
            "z": 0,
            "elements": [
                "immersiveengineering:storage@8"
            ]
        },
        {
            "x": 1,
            "y": 3,
            "z": 0,
            "elements": [
                "immersiveengineering:storage@8"
            ]
        },
        {
            "x": -4,
            "y": -1,
            "z": 2,
            "elements": [
                "immersiveengineering:storage@8"
            ]
        },
        {
            "x": 2,
            "y": 3,
            "z": 0,
            "elements": [
                "immersiveengineering:storage@8"
            ]
        },
        {
            "x": -3,
            "y": -1,
            "z": 2,
            "nbt": {"casingColor":"16730368","id":"minecraft:tilecolorablemachinecomponent"},
            "elements": [
                "modularmachinery:blockcasing@0"
            ]
        },
        {
            "x": -2,
            "y": -1,
            "z": 2,
            "elements": [
                "immersiveengineering:storage@8"
            ]
        },
        {
            "x": -1,
            "y": -1,
            "z": 2,
            "nbt": {"casingColor":"16730368","id":"minecraft:tilecolorablemachinecomponent"},
            "elements": [
                "modularmachinery:blockcasing@0"
            ]
        },
        {
            "x": 0,
            "y": -1,
            "z": 2,
            "nbt": {"casingColor":"16730368","id":"minecraft:tilecolorablemachinecomponent"},
            "elements": [
                "modularmachinery:blockcasing@0"
            ]
        },
        {
            "x": 1,
            "y": -1,
            "z": 2,
            "nbt": {"casingColor":"16730368","id":"minecraft:tilecolorablemachinecomponent"},
            "elements": [
                "modularmachinery:blockcasing@0"
            ]
        },
        {
            "x": 2,
            "y": -1,
            "z": 2,
            "elements": [
                "immersiveengineering:storage@8"
            ]
        },
        {
            "x": 3,
            "y": -1,
            "z": 2,
            "nbt": {"casingColor":"16730368","id":"minecraft:tilecolorablemachinecomponent"},
            "elements": [
                "modularmachinery:blockcasing@0"
            ]
        },
        {
            "x": 4,
            "y": -1,
            "z": 2,
            "nbt": {"casingColor":"16730368","id":"minecraft:tilecolorablemachinecomponent"},
            "elements": [
                "modularmachinery:blockcasing@0"
            ]
        },
        {
            "x": 5,
            "y": -1,
            "z": 2,
            "elements": [
                "immersiveengineering:storage@8"
            ]
        },
        {
            "x": -2,
            "y": 4,
            "z": 0,
            "nbt": {"id":"immersiveengineering:ieslab","slabType":"0"},
            "elements": [
                "immersiveengineering:sheetmetal_slab@8"
            ]
        },
        {
            "x": -1,
            "y": 4,
            "z": 0,
            "nbt": {"id":"immersiveengineering:ieslab","slabType":"0"},
            "elements": [
                "immersiveengineering:sheetmetal_slab@8"
            ]
        },
        {
            "x": 0,
            "y": 4,
            "z": 0,
            "nbt": {"id":"immersiveengineering:ieslab","slabType":"0"},
            "elements": [
                "immersiveengineering:sheetmetal_slab@8"
            ]
        },
        {
            "x": 1,
            "y": 4,
            "z": 0,
            "nbt": {"id":"immersiveengineering:ieslab","slabType":"0"},
            "elements": [
                "immersiveengineering:sheetmetal_slab@8"
            ]
        },
        {
            "x": -4,
            "y": 0,
            "z": 2,
            "elements": [
                "immersiveengineering:storage@8"
            ]
        },
        {
            "x": 2,
            "y": 4,
            "z": 0,
            "nbt": {"id":"immersiveengineering:ieslab","slabType":"0"},
            "elements": [
                "immersiveengineering:sheetmetal_slab@8"
            ]
        },
        {
            "x": -3,
            "y": 0,
            "z": 2,
            "nbt": {"casingColor":"16730368","id":"minecraft:tilecolorablemachinecomponent"},
            "elements": [
                "modularmachinery:blockcasing@0"
            ]
        },
        {
            "x": -2,
            "y": 0,
            "z": 2,
            "elements": [
                "immersiveengineering:storage@8"
            ]
        },
        {
            "x": -1,
            "y": 0,
            "z": 2,
            "nbt": {"casingColor":"16730368","id":"minecraft:tilecolorablemachinecomponent"},
            "elements": [
                "modularmachinery:blockcasing@0"
            ]
        },
        {
            "x": 0,
            "y": 0,
            "z": 2,
            "nbt": {"casingColor":"16730368","id":"minecraft:tilecolorablemachinecomponent"},
            "elements": [
                "modularmachinery:blockcasing@0"
            ]
        },
        {
            "x": 1,
            "y": 0,
            "z": 2,
            "nbt": {"casingColor":"16730368","id":"minecraft:tilecolorablemachinecomponent"},
            "elements": [
                "modularmachinery:blockcasing@0"
            ]
        },
        {
            "x": 2,
            "y": 0,
            "z": 2,
            "elements": [
                "immersiveengineering:storage@8"
            ]
        },
        {
            "x": 3,
            "y": 0,
            "z": 2,
            "nbt": {"casingColor":"16730368","id":"minecraft:tilecolorablemachinecomponent"},
            "elements": [
                "modularmachinery:blockcasing@0"
            ]
        },
        {
            "x": 4,
            "y": 0,
            "z": 2,
            "nbt": {"casingColor":"16730368","id":"minecraft:tilecolorablemachinecomponent"},
            "elements": [
                "modularmachinery:blockcasing@0"
            ]
        },
        {
            "x": 5,
            "y": 0,
            "z": 2,
            "elements": [
                "immersiveengineering:storage@8"
            ]
        },
        {
            "x": -4,
            "y": 1,
            "z": 2,
            "nbt": {"id":"immersiveengineering:ieslab","slabType":"0"},
            "elements": [
                "immersiveengineering:sheetmetal_slab@8"
            ]
        },
        {
            "x": -4,
            "y": -1,
            "z": 1,
            "elements": [
                "immersiveengineering:storage@8"
            ]
        },
        {
            "x": -3,
            "y": 1,
            "z": 2,
            "nbt": {"id":"immersiveengineering:ieslab","slabType":"0"},
            "elements": [
                "immersiveengineering:sheetmetal_slab@8"
            ]
        },
        {
            "x": -3,
            "y": -1,
            "z": 1,
            "nbt": {"casingColor":"16730368","id":"minecraft:tilecolorablemachinecomponent"},
            "elements": [
                "modularmachinery:blockcasing@0"
            ]
        },
        {
            "x": -2,
            "y": 1,
            "z": 2,
            "elements": [
                "immersiveengineering:storage@8"
            ]
        },
        {
            "x": -2,
            "y": -1,
            "z": 1,
            "nbt": {"casingColor":"16730368","id":"minecraft:tilecolorablemachinecomponent"},
            "elements": [
                "modularmachinery:blockcasing@0"
            ]
        },
        {
            "x": -1,
            "y": 1,
            "z": 2,
            "nbt": {"casingColor":"16730368","id":"minecraft:tilecolorablemachinecomponent"},
            "elements": [
                "modularmachinery:blockcasing@0"
            ]
        },
        {
            "x": 0,
            "y": 1,
            "z": 2,
            "nbt": {"casingColor":"16730368","id":"minecraft:tilecolorablemachinecomponent"},
            "elements": [
                "modularmachinery:blockcasing@0"
            ]
        },
        {
            "x": -1,
            "y": -1,
            "z": 1,
            "nbt": {"casingColor":"16730368","id":"minecraft:tilecolorablemachinecomponent"},
            "elements": [
                "modularmachinery:blockcasing@0"
            ]
        },
        {
            "x": 0,
            "y": -1,
            "z": 1,
            "nbt": {"casingColor":"16730368","id":"minecraft:tilecolorablemachinecomponent"},
            "elements": [
                "modularmachinery:blockcasing@0"
            ]
        },
        {
            "x": 1,
            "y": 1,
            "z": 2,
            "nbt": {"casingColor":"16730368","id":"minecraft:tilecolorablemachinecomponent"},
            "elements": [
                "modularmachinery:blockcasing@0"
            ]
        },
        {
            "x": 2,
            "y": 1,
            "z": 2,
            "elements": [
                "immersiveengineering:storage@8"
            ]
        },
        {
            "x": 1,
            "y": -1,
            "z": 1,
            "nbt": {"casingColor":"16730368","id":"minecraft:tilecolorablemachinecomponent"},
            "elements": [
                "modularmachinery:blockcasing@0"
            ]
        },
        {
            "x": 3,
            "y": 1,
            "z": 2,
            "nbt": {"id":"immersiveengineering:ieslab","slabType":"0"},
            "elements": [
                "immersiveengineering:sheetmetal_slab@8"
            ]
        },
        {
            "x": 2,
            "y": -1,
            "z": 1,
            "nbt": {"casingColor":"16730368","id":"minecraft:tilecolorablemachinecomponent"},
            "elements": [
                "modularmachinery:blockcasing@0"
            ]
        },
        {
            "x": 4,
            "y": 1,
            "z": 2,
            "nbt": {"id":"immersiveengineering:ieslab","slabType":"0"},
            "elements": [
                "immersiveengineering:sheetmetal_slab@8"
            ]
        },
        {
            "x": 3,
            "y": -1,
            "z": 1,
            "nbt": {"casingColor":"16730368","id":"minecraft:tilecolorablemachinecomponent"},
            "elements": [
                "modularmachinery:blockcasing@0"
            ]
        },
        {
            "x": 5,
            "y": 1,
            "z": 2,
            "nbt": {"id":"immersiveengineering:ieslab","slabType":"0"},
            "elements": [
                "immersiveengineering:sheetmetal_slab@8"
            ]
        },
        {
            "x": 4,
            "y": -1,
            "z": 1,
            "nbt": {"casingColor":"16730368","id":"minecraft:tilecolorablemachinecomponent"},
            "elements": [
                "modularmachinery:blockcasing@0"
            ]
        },
        {
            "x": 5,
            "y": -1,
            "z": 1,
            "nbt": {"casingColor":"16730368","id":"minecraft:tilecolorablemachinecomponent"},
            "elements": [
                "modularmachinery:blockcasing@0"
            ]
        },
        {
            "x": -4,
            "y": 0,
            "z": 1,
            "nbt": {"conveyorBeltSubtypeNBT":{"dyeColour":"-1","direction":"0"},"facing":"2","conveyorBeltSubtype":"immersiveengineering:conveyor","id":"immersiveengineering:conveyorbelt"},
            "elements": [
                "immersiveengineering:conveyor@0"
            ]
        },
        {
            "x": -3,
            "y": 0,
            "z": 1,
            "nbt": {"conveyorBeltSubtypeNBT":{"transferTickrate":"8","extractDirection":"3","dyeColour":"-1","direction":"0"},"facing":"2","conveyorBeltSubtype":"immersiveengineering:extract","id":"immersiveengineering:conveyorbelt"},
            "elements": [
                "immersiveengineering:conveyor@0"
            ]
        },
        {
            "x": -2,
            "y": 2,
            "z": 2,
            "elements": [
                "immersiveengineering:storage@8"
            ]
        },
        {
            "x": -2,
            "y": 0,
            "z": 1,
            "nbt": {"busSize":"1","casingColor":"16730368","id":"minecraft:tileitemoutputbus"},
            "elements": [
                "modularmachinery:blockoutputbus@1"
            ]
        },
        {
            "x": -1,
            "y": 2,
            "z": 2,
            "elements": [
                "minecraft:glass@0"
            ]
        },
        {
            "x": 0,
            "y": 2,
            "z": 2,
            "elements": [
                "minecraft:glass@0"
            ]
        },
        {
            "x": -1,
            "y": 0,
            "z": 1,
            "nbt": {"busSize":"1","casingColor":"16730368","id":"minecraft:tileiteminputbus"},
            "elements": [
                "modularmachinery:blockinputbus@1"
            ]
        },
        {
            "x": 0,
            "y": 0,
            "z": 1,
            "nbt": {"casingColor":"16730368","id":"minecraft:tilecolorablemachinecomponent"},
            "elements": [
                "modularmachinery:blockcasing@0"
            ]
        },
        {
            "x": 1,
            "y": 2,
            "z": 2,
            "elements": [
                "minecraft:glass@0"
            ]
        },
        {
            "x": 2,
            "y": 2,
            "z": 2,
            "elements": [
                "immersiveengineering:storage@8"
            ]
        },
        {
            "x": 1,
            "y": 0,
            "z": 1,
            "nbt": {"busSize":"1","casingColor":"16730368","id":"minecraft:tileiteminputbus"},
            "elements": [
                "modularmachinery:blockinputbus@1"
            ]
        },
        {
            "x": 2,
            "y": 0,
            "z": 1,
            "nbt": {"casingColor":"16730368","id":"minecraft:tilecolorablemachinecomponent"},
            "elements": [
                "modularmachinery:blockcasing@0"
            ]
        },
        {
            "x": 3,
            "y": 0,
            "z": 1,
            "elements": [
                "immersiveengineering:metal_decoration0@5"
            ]
        },
        {
            "x": 4,
            "y": 0,
            "z": 1,
            "elements": [
                "immersiveengineering:metal_decoration0@5"
            ]
        },
        {
            "x": 5,
            "y": 0,
            "z": 1,
            "nbt": {"casingColor":"16730368","id":"minecraft:tilecolorablemachinecomponent"},
            "elements": [
                "modularmachinery:blockcasing@0"
            ]
        },
        {
            "x": -4,
            "y": 1,
            "z": 1,
            "nbt": {"id":"immersiveengineering:ieslab","slabType":"0"},
            "elements": [
                "immersiveengineering:sheetmetal_slab@8"
            ]
        },
        {
            "x": -3,
            "y": 1,
            "z": 1,
            "nbt": {"id":"immersiveengineering:ieslab","slabType":"0"},
            "elements": [
                "immersiveengineering:sheetmetal_slab@8"
            ]
        },
        {
            "x": -2,
            "y": 3,
            "z": 2,
            "elements": [
                "immersiveengineering:storage@8"
            ]
        },
        {
            "x": -2,
            "y": 1,
            "z": 1,
            "nbt": {"casingColor":"16730368","id":"minecraft:tilecolorablemachinecomponent"},
            "elements": [
                "modularmachinery:blockcasing@0"
            ]
        },
        {
            "x": -1,
            "y": 3,
            "z": 2,
            "elements": [
                "immersiveengineering:storage@8"
            ]
        },
        {
            "x": 0,
            "y": 3,
            "z": 2,
            "elements": [
                "immersiveengineering:storage@8"
            ]
        },
        {
            "x": -1,
            "y": 1,
            "z": 1,
            "elements": [
                "minecraft:hopper@0"
            ]
        },
        {
            "x": 1,
            "y": 3,
            "z": 2,
            "elements": [
                "immersiveengineering:storage@8"
            ]
        },
        {
            "x": 0,
            "y": 1,
            "z": 1,
            "elements": [
                "immersiveengineering:metal_decoration0@4"
            ]
        },
        {
            "x": 2,
            "y": 3,
            "z": 2,
            "elements": [
                "immersiveengineering:storage@8"
            ]
        },
        {
            "x": 1,
            "y": 1,
            "z": 1,
            "elements": [
                "minecraft:hopper@0"
            ]
        },
        {
            "x": 2,
            "y": 1,
            "z": 1,
            "nbt": {"casingColor":"16730368","id":"minecraft:tilecolorablemachinecomponent"},
            "elements": [
                "modularmachinery:blockcasing@0"
            ]
        },
        {
            "x": 3,
            "y": 1,
            "z": 1,
            "nbt": {"id":"immersiveengineering:ieslab","slabType":"0"},
            "elements": [
                "immersiveengineering:sheetmetal_slab@8"
            ]
        },
        {
            "x": 4,
            "y": 1,
            "z": 1,
            "nbt": {"id":"immersiveengineering:ieslab","slabType":"0"},
            "elements": [
                "immersiveengineering:sheetmetal_slab@8"
            ]
        },
        {
            "x": 5,
            "y": 1,
            "z": 1,
            "nbt": {"hatchSize":"1","casingColor":"16730368","id":"minecraft:tileenergyinputhatch"},
            "elements": [
                "modularmachinery:blockenergyinputhatch@1"
            ]
        },
        {
            "x": -2,
            "y": 4,
            "z": 2,
            "nbt": {"id":"immersiveengineering:ieslab","slabType":"0"},
            "elements": [
                "immersiveengineering:sheetmetal_slab@8"
            ]
        },
        {
            "x": -2,
            "y": 2,
            "z": 1,
            "nbt": {"casingColor":"16730368","id":"minecraft:tilecolorablemachinecomponent"},
            "elements": [
                "modularmachinery:blockcasing@0"
            ]
        },
        {
            "x": -1,
            "y": 4,
            "z": 2,
            "nbt": {"id":"immersiveengineering:ieslab","slabType":"0"},
            "elements": [
                "immersiveengineering:sheetmetal_slab@8"
            ]
        },
        {
            "x": 0,
            "y": 4,
            "z": 2,
            "nbt": {"id":"immersiveengineering:ieslab","slabType":"0"},
            "elements": [
                "immersiveengineering:sheetmetal_slab@8"
            ]
        },
        {
            "x": 1,
            "y": 4,
            "z": 2,
            "nbt": {"id":"immersiveengineering:ieslab","slabType":"0"},
            "elements": [
                "immersiveengineering:sheetmetal_slab@8"
            ]
        },
        {
            "x": 0,
            "y": 2,
            "z": 1,
            "elements": [
                "immersiveengineering:metal_decoration0@4"
            ]
        }
    ]}