{
	"registryname": "concreteplant",
    "localizedname": "Concrete Plant",
	
    "parts": [
        {
            "x": -1,
            "y": 0,
            "z": 0,
            "elements": [
                "immersiveengineering:metal_decoration1@0"
            ]
        },
        {
            "x": 1,
            "y": 0,
            "z": 0,
            "elements": [
                "immersiveengineering:metal_decoration1@0"
            ]
        },
        {
            "x": 3,
            "y": 0,
            "z": 0,
            "elements": [
                "immersiveengineering:storage@8"
            ]
        },
        {
            "x": 4,
            "y": 0,
            "z": 0,
            "elements": [
                "immersiveengineering:storage@8"
            ]
        },
        {
            "x": 5,
            "y": 0,
            "z": 0,
            "elements": [
                "immersiveengineering:storage@8"
            ]
        },
        {
            "x": 8,
            "y": 0,
            "z": 0,
            "elements": [
                "immersiveengineering:metal_decoration1@1"
            ]
        },
        {
            "x": 11,
            "y": 0,
            "z": 0,
            "elements": [
                "immersiveengineering:metal_decoration1@1"
            ]
        },
        {
            "x": 12,
            "y": 0,
            "z": 0,
            "nbt": {"conveyorBeltSubtypeNBT":{"cover":{"id":"minecraft:air","Count":"1b","Damage":"0s"},"dyeColour":"-1","direction":"1"},"facing":"4","conveyorBeltSubtype":"immersiveengineering:covered","id":"immersiveengineering:conveyorbelt"},
            "elements": [
                "immersiveengineering:conveyor@0"
            ]
        },
        {
            "x": 16,
            "y": -1,
            "z": 0,
            "elements": [
                "immersiveengineering:metal_decoration1@0"
            ]
        },
        {
            "x": 15,
            "y": -1,
            "z": 0,
            "nbt": {"conveyorBeltSubtypeNBT":{"dyeColour":"-1","direction":"0"},"facing":"4","conveyorBeltSubtype":"immersiveengineering:conveyor","id":"immersiveengineering:conveyorbelt"},
            "elements": [
                "immersiveengineering:conveyor@0"
            ]
        },
        {
            "x": 14,
            "y": -1,
            "z": 0,
            "nbt": {"conveyorBeltSubtypeNBT":{"cover":{"id":"minecraft:air","Count":"1b","Damage":"0s"},"dyeColour":"-1","direction":"0"},"facing":"4","conveyorBeltSubtype":"immersiveengineering:covered","id":"immersiveengineering:conveyorbelt"},
            "elements": [
                "immersiveengineering:conveyor@0"
            ]
        },
        {
            "x": 13,
            "y": -1,
            "z": 0,
            "nbt": {"conveyorBeltSubtypeNBT":{"cover":{"id":"minecraft:air","Count":"1b","Damage":"0s"},"dyeColour":"-1","direction":"1"},"facing":"4","conveyorBeltSubtype":"immersiveengineering:covered","id":"immersiveengineering:conveyorbelt"},
            "elements": [
                "immersiveengineering:conveyor@0"
            ]
        },
        {
            "x": 11,
            "y": -1,
            "z": 0,
            "elements": [
                "immersiveengineering:metal_decoration1@1"
            ]
        },
        {
            "x": -10,
            "y": 5,
            "z": 2,
            "elements": [
                "immersiveengineering:metal_multiblock"
            ]
        },
        {
            "x": -9,
            "y": 5,
            "z": 2,
            "elements": [
                "immersiveengineering:metal_multiblock"
            ]
        },
        {
            "x": -8,
            "y": 5,
            "z": 2,
            "elements": [
                "immersiveengineering:metal_multiblock"
            ]
        },
        {
            "x": 8,
            "y": -1,
            "z": 0,
            "elements": [
                "immersiveengineering:metal_decoration1@1"
            ]
        },
        {
            "x": -7,
            "y": 5,
            "z": 2,
            "nbt": {"conveyorBeltSubtypeNBT":{"cover":{"id":"minecraft:air","Count":"1b","Damage":"0s"},"dyeColour":"-1","direction":"1"},"facing":"4","conveyorBeltSubtype":"immersiveengineering:covered","id":"immersiveengineering:conveyorbelt"},
            "elements": [
                "immersiveengineering:conveyor@0"
            ]
        },
        {
            "x": 5,
            "y": -1,
            "z": 0,
            "elements": [
                "immersiveengineering:storage@8"
            ]
        },
        {
            "x": 4,
            "y": -1,
            "z": 0,
            "nbt": {"busSize":"1","casingColor":"16730368","id":"minecraft:tileitemoutputbus"}, 
            "elements": [
                "modularmachinery:blockoutputbus@1"
            ]
        },
        {
            "x": 3,
            "y": -1,
            "z": 0,
            "elements": [
                "immersiveengineering:storage@8"
            ]
        },
        {
            "x": 1,
            "y": -1,
            "z": 0,
            "elements": [
                "immersiveengineering:metal_decoration1@0"
            ]
        },
        {
            "x": -1,
            "y": 1,
            "z": 0,
            "elements": [
                "immersiveengineering:metal_decoration1@0"
            ]
        },
        {
            "x": 0,
            "y": -1,
            "z": 0,
            "nbt": {"casingColor":"16730368","id":"minecraft:tilecolorablemachinecomponent"},
            "elements": [
                "modularmachinery:blockcasing@0"
            ]
        },
        {
            "x": -1,
            "y": -1,
            "z": 0,
            "elements": [
                "immersiveengineering:metal_decoration1@0"
            ]
        },
        {
            "x": 0,
            "y": 1,
            "z": 0,
			
            "elements": [
                "modularmachinery:blockenergyinputhatch@1"
            ]
        },
        {
            "x": 1,
            "y": 1,
            "z": 0,
            "elements": [
                "immersiveengineering:metal_decoration1@0"
            ]
        },
        {
            "x": 4,
            "y": 1,
            "z": 0,
            "elements": [
                "immersiveengineering:metal_decoration1@1"
            ]
        },
        {
            "x": 8,
            "y": 1,
            "z": 0,
            "elements": [
                "immersiveengineering:metal_decoration1@1"
            ]
        },
        {
            "x": 10,
            "y": 1,
            "z": 0,
            "nbt": {"conveyorBeltSubtypeNBT":{"cover":{"id":"minecraft:air","Count":"1b","Damage":"0s"},"dyeColour":"-1","direction":"1"},"facing":"4","conveyorBeltSubtype":"immersiveengineering:covered","id":"immersiveengineering:conveyorbelt"},
            "elements": [
                "immersiveengineering:conveyor@0"
            ]
        },
        {
            "x": 11,
            "y": 1,
            "z": 0,
            "nbt": {"conveyorBeltSubtypeNBT":{"cover":{"id":"minecraft:air","Count":"1b","Damage":"0s"},"dyeColour":"-1","direction":"0"},"facing":"4","conveyorBeltSubtype":"immersiveengineering:covered","id":"immersiveengineering:conveyorbelt"},
            "elements": [
                "immersiveengineering:conveyor@0"
            ]
        },
        {
            "x": -9,
            "y": 6,
            "z": 2,
            "nbt": {"conveyorBeltSubtypeNBT":{"cover":{"id":"minecraft:air","Count":"1b","Damage":"0s"},"dyeColour":"-1","direction":"0"},"facing":"4","conveyorBeltSubtype":"immersiveengineering:droppercovered","id":"immersiveengineering:conveyorbelt"},
            "elements": [
                "immersiveengineering:conveyor@0"
            ]
        },
        {
            "x": -8,
            "y": 6,
            "z": 2,
            "nbt": {"conveyorBeltSubtypeNBT":{"cover":{"id":"minecraft:air","Count":"1b","Damage":"0s"},"dyeColour":"-1","direction":"0"},"facing":"4","conveyorBeltSubtype":"immersiveengineering:covered","id":"immersiveengineering:conveyorbelt"},
            "elements": [
                "immersiveengineering:conveyor@0"
            ]
        },
        {
            "x": 21,
            "y": 4,
            "z": -13,
            "nbt": {"conveyorBeltSubtypeNBT":{"dyeColour":"-1","direction":"0"},"facing":"2","conveyorBeltSubtype":"immersiveengineering:conveyor","id":"immersiveengineering:conveyorbelt"},
            "elements": [
                "immersiveengineering:conveyor@0"
            ]
        },
        {
            "x": 20,
            "y": 4,
            "z": -13,
            "nbt": {"conveyorBeltSubtypeNBT":{"dyeColour":"-1","direction":"0"},"facing":"5","conveyorBeltSubtype":"immersiveengineering:conveyor","id":"immersiveengineering:conveyorbelt"},
            "elements": [
                "immersiveengineering:conveyor@0"
            ]
        },
        {
            "x": 19,
            "y": 4,
            "z": -13,
            "nbt": {"conveyorBeltSubtypeNBT":{"dyeColour":"-1","direction":"0"},"facing":"5","conveyorBeltSubtype":"immersiveengineering:conveyor","id":"immersiveengineering:conveyorbelt"},
            "elements": [
                "immersiveengineering:conveyor@0"
            ]
        },
        {
            "x": 18,
            "y": 4,
            "z": -13,
            "nbt": {"conveyorBeltSubtypeNBT":{"dyeColour":"-1","direction":"0"},"facing":"5","conveyorBeltSubtype":"immersiveengineering:conveyor","id":"immersiveengineering:conveyorbelt"},
            "elements": [
                "immersiveengineering:conveyor@0"
            ]
        },
        {
            "x": 17,
            "y": 4,
            "z": -13,
            "nbt": {"conveyorBeltSubtypeNBT":{"dyeColour":"-1","direction":"0"},"facing":"5","conveyorBeltSubtype":"immersiveengineering:conveyor","id":"immersiveengineering:conveyorbelt"},
            "elements": [
                "immersiveengineering:conveyor@0"
            ]
        },
        {
            "x": 16,
            "y": 4,
            "z": -13,
            "nbt": {"conveyorBeltSubtypeNBT":{"dyeColour":"-1","direction":"0"},"facing":"5","conveyorBeltSubtype":"immersiveengineering:conveyor","id":"immersiveengineering:conveyorbelt"},
            "elements": [
                "immersiveengineering:conveyor@0"
            ]
        },
        {
            "x": 15,
            "y": 4,
            "z": -13,
            "nbt": {"conveyorBeltSubtypeNBT":{"dyeColour":"-1","direction":"0"},"facing":"5","conveyorBeltSubtype":"immersiveengineering:conveyor","id":"immersiveengineering:conveyorbelt"},
            "elements": [
                "immersiveengineering:conveyor@0"
            ]
        },
        {
            "x": 14,
            "y": 4,
            "z": -13,
            "nbt": {"conveyorBeltSubtypeNBT":{"dyeColour":"-1","direction":"0"},"facing":"5","conveyorBeltSubtype":"immersiveengineering:conveyor","id":"immersiveengineering:conveyorbelt"},
            "elements": [
                "immersiveengineering:conveyor@0"
            ]
        },
        {
            "x": 4,
            "y": 2,
            "z": 0,
            "elements": [
                "immersiveengineering:metal_decoration1@1"
            ]
        },
        {
            "x": 13,
            "y": 4,
            "z": -13,
            "nbt": {"conveyorBeltSubtypeNBT":{"dyeColour":"-1","direction":"0"},"facing":"5","conveyorBeltSubtype":"immersiveengineering:conveyor","id":"immersiveengineering:conveyorbelt"},
            "elements": [
                "immersiveengineering:conveyor@0"
            ]
        },
        {
            "x": 5,
            "y": 2,
            "z": 0,
            "elements": [
                "immersiveengineering:metal_decoration1@1"
            ]
        },
        {
            "x": 12,
            "y": 4,
            "z": -13,
            "nbt": {"conveyorBeltSubtypeNBT":{"dyeColour":"-1","direction":"0"},"facing":"5","conveyorBeltSubtype":"immersiveengineering:conveyor","id":"immersiveengineering:conveyorbelt"},
            "elements": [
                "immersiveengineering:conveyor@0"
            ]
        },
        {
            "x": 6,
            "y": 2,
            "z": 0,
            "elements": [
                "immersiveengineering:metal_decoration1@1"
            ]
        },
        {
            "x": 11,
            "y": 4,
            "z": -13,
            "nbt": {"conveyorBeltSubtypeNBT":{"dyeColour":"-1","direction":"0"},"facing":"5","conveyorBeltSubtype":"immersiveengineering:conveyor","id":"immersiveengineering:conveyorbelt"},
            "elements": [
                "immersiveengineering:conveyor@0"
            ]
        },
        {
            "x": 7,
            "y": 2,
            "z": 0,
            "elements": [
                "immersiveengineering:metal_decoration1@1"
            ]
        },
        {
            "x": 10,
            "y": 4,
            "z": -13,
            "nbt": {"conveyorBeltSubtypeNBT":{"dyeColour":"-1","direction":"0"},"facing":"5","conveyorBeltSubtype":"immersiveengineering:conveyor","id":"immersiveengineering:conveyorbelt"},
            "elements": [
                "immersiveengineering:conveyor@0"
            ]
        },
        {
            "x": 8,
            "y": 2,
            "z": 0,
            "elements": [
                "immersiveengineering:metal_decoration1@1"
            ]
        },
        {
            "x": 9,
            "y": 4,
            "z": -13,
            "nbt": {"conveyorBeltSubtypeNBT":{"dyeColour":"-1","direction":"0"},"facing":"5","conveyorBeltSubtype":"immersiveengineering:conveyor","id":"immersiveengineering:conveyorbelt"},
            "elements": [
                "immersiveengineering:conveyor@0"
            ]
        },
        {
            "x": 9,
            "y": 2,
            "z": 0,
            "nbt": {"conveyorBeltSubtypeNBT":{"cover":{"id":"minecraft:air","Count":"1b","Damage":"0s"},"dyeColour":"-1","direction":"1"},"facing":"4","conveyorBeltSubtype":"immersiveengineering:covered","id":"immersiveengineering:conveyorbelt"},
            "elements": [
                "immersiveengineering:conveyor@0"
            ]
        },
        {
            "x": 8,
            "y": 4,
            "z": -13,
            "nbt": {"conveyorBeltSubtypeNBT":{"dyeColour":"-1","direction":"0"},"facing":"5","conveyorBeltSubtype":"immersiveengineering:conveyor","id":"immersiveengineering:conveyorbelt"},
            "elements": [
                "immersiveengineering:conveyor@0"
            ]
        },
        {
            "x": 7,
            "y": 4,
            "z": -13,
            "nbt": {"conveyorBeltSubtypeNBT":{"dyeColour":"-1","direction":"0"},"facing":"5","conveyorBeltSubtype":"immersiveengineering:conveyor","id":"immersiveengineering:conveyorbelt"},
            "elements": [
                "immersiveengineering:conveyor@0"
            ]
        },
        {
            "x": 6,
            "y": 4,
            "z": -13,
            "nbt": {"conveyorBeltSubtypeNBT":{"dyeColour":"-1","direction":"0"},"facing":"5","conveyorBeltSubtype":"immersiveengineering:conveyor","id":"immersiveengineering:conveyorbelt"},
            "elements": [
                "immersiveengineering:conveyor@0"
            ]
        },
        {
            "x": 5,
            "y": 4,
            "z": -13,
            "nbt": {"conveyorBeltSubtypeNBT":{"dyeColour":"-1","direction":"0"},"facing":"5","conveyorBeltSubtype":"immersiveengineering:conveyor","id":"immersiveengineering:conveyorbelt"},
            "elements": [
                "immersiveengineering:conveyor@0"
            ]
        },
        {
            "x": 21,
            "y": -1,
            "z": -15,
            "nbt": {"conveyorBeltSubtypeNBT":{"cover":{"id":"minecraft:air","Count":"1b","Damage":"0s"},"dyeColour":"-1","direction":"1"},"facing":"3","conveyorBeltSubtype":"immersiveengineering:covered","id":"immersiveengineering:conveyorbelt"},
            "elements": [
                "immersiveengineering:conveyor@0"
            ]
        },
        {
            "x": 21,
            "y": 3,
            "z": -13,
            "elements": [
                "immersiveengineering:metal_decoration1@1"
            ]
        },
        {
            "x": 20,
            "y": 3,
            "z": -13,
            "elements": [
                "immersiveengineering:metal_decoration1@1"
            ]
        },
        {
            "x": 19,
            "y": 3,
            "z": -13,
            "elements": [
                "immersiveengineering:metal_decoration1@1"
            ]
        },
        {
            "x": 18,
            "y": 3,
            "z": -13,
            "elements": [
                "immersiveengineering:metal_decoration1@1"
            ]
        },
        {
            "x": 15,
            "y": -1,
            "z": -15,
            "nbt": {"conveyorBeltSubtypeNBT":{"cover":{"id":"minecraft:air","Count":"1b","Damage":"0s"},"dyeColour":"-1","direction":"1"},"facing":"3","conveyorBeltSubtype":"immersiveengineering:covered","id":"immersiveengineering:conveyorbelt"},
            "elements": [
                "immersiveengineering:conveyor@0"
            ]
        },
        {
            "x": 17,
            "y": 3,
            "z": -13,
            "elements": [
                "immersiveengineering:metal_decoration1@1"
            ]
        },
        {
            "x": 16,
            "y": 3,
            "z": -13,
            "elements": [
                "immersiveengineering:metal_decoration1@1"
            ]
        },
        {
            "x": 15,
            "y": 3,
            "z": -13,
            "elements": [
                "immersiveengineering:metal_decoration1@1"
            ]
        },
        {
            "x": 14,
            "y": 3,
            "z": -13,
            "elements": [
                "immersiveengineering:metal_decoration1@1"
            ]
        },
        {
            "x": 4,
            "y": 3,
            "z": 0,
            "nbt": {"conveyorBeltSubtypeNBT":{"dyeColour":"-1","direction":"0"},"facing":"2","conveyorBeltSubtype":"immersiveengineering:conveyor","id":"immersiveengineering:conveyorbelt"},
            "elements": [
                "immersiveengineering:conveyor@0"
            ]
        },
        {
            "x": 13,
            "y": 3,
            "z": -13,
            "elements": [
                "immersiveengineering:metal_decoration1@1"
            ]
        },
        {
            "x": 5,
            "y": 3,
            "z": 0,
            "nbt": {"conveyorBeltSubtypeNBT":{"dyeColour":"-1","direction":"0"},"facing":"4","conveyorBeltSubtype":"immersiveengineering:conveyor","id":"immersiveengineering:conveyorbelt"},
            "elements": [
                "immersiveengineering:conveyor@0"
            ]
        },
        {
            "x": 12,
            "y": 3,
            "z": -13,
            "elements": [
                "immersiveengineering:metal_decoration1@1"
            ]
        },
        {
            "x": 6,
            "y": 3,
            "z": 0,
            "nbt": {"conveyorBeltSubtypeNBT":{"dyeColour":"-1","direction":"0"},"facing":"4","conveyorBeltSubtype":"immersiveengineering:conveyor","id":"immersiveengineering:conveyorbelt"},
            "elements": [
                "immersiveengineering:conveyor@0"
            ]
        },
        {
            "x": 9,
            "y": -1,
            "z": -15,
            "nbt": {"conveyorBeltSubtypeNBT":{"cover":{"id":"minecraft:air","Count":"1b","Damage":"0s"},"dyeColour":"-1","direction":"1"},"facing":"3","conveyorBeltSubtype":"immersiveengineering:covered","id":"immersiveengineering:conveyorbelt"},
            "elements": [
                "immersiveengineering:conveyor@0"
            ]
        },
        {
            "x": 11,
            "y": 3,
            "z": -13,
            "elements": [
                "immersiveengineering:metal_decoration1@1"
            ]
        },
        {
            "x": 7,
            "y": 3,
            "z": 0,
            "nbt": {"conveyorBeltSubtypeNBT":{"dyeColour":"-1","direction":"0"},"facing":"4","conveyorBeltSubtype":"immersiveengineering:conveyor","id":"immersiveengineering:conveyorbelt"},
            "elements": [
                "immersiveengineering:conveyor@0"
            ]
        },
        {
            "x": 10,
            "y": 3,
            "z": -13,
            "elements": [
                "immersiveengineering:metal_decoration1@1"
            ]
        },
        {
            "x": 8,
            "y": 3,
            "z": 0,
            "nbt": {"conveyorBeltSubtypeNBT":{"cover":{"id":"minecraft:air","Count":"1b","Damage":"0s"},"dyeColour":"-1","direction":"0"},"facing":"4","conveyorBeltSubtype":"immersiveengineering:covered","id":"immersiveengineering:conveyorbelt"},
            "elements": [
                "immersiveengineering:conveyor@0"
            ]
        },
        {
            "x": 9,
            "y": 3,
            "z": -13,
            "elements": [
                "immersiveengineering:metal_decoration1@1"
            ]
        },
        {
            "x": 8,
            "y": 3,
            "z": -13,
            "elements": [
                "immersiveengineering:metal_decoration1@1"
            ]
        },
        {
            "x": 7,
            "y": 3,
            "z": -13,
            "elements": [
                "immersiveengineering:metal_decoration1@1"
            ]
        },
        {
            "x": 6,
            "y": 3,
            "z": -13,
            "elements": [
                "immersiveengineering:metal_decoration1@1"
            ]
        },
        {
            "x": 5,
            "y": 3,
            "z": -13,
            "elements": [
                "immersiveengineering:metal_decoration1@1"
            ]
        },
        {
            "x": 4,
            "y": 3,
            "z": -13,
            "nbt": {"conveyorBeltSubtypeNBT":{"dyeColour":"-1","direction":"0"},"facing":"5","conveyorBeltSubtype":"immersiveengineering:vertical","id":"immersiveengineering:conveyorbelt"},
            "elements": [
                "immersiveengineering:conveyor@0"
            ]
        },
        {
            "x": 21,
            "y": 2,
            "z": -13,
            "elements": [
                "immersiveengineering:metal_decoration1@1"
            ]
        },
        {
            "x": 15,
            "y": 2,
            "z": -13,
            "elements": [
                "immersiveengineering:metal_decoration1@1"
            ]
        },
        {
            "x": 9,
            "y": 2,
            "z": -13,
            "elements": [
                "immersiveengineering:metal_decoration1@1"
            ]
        },
        {
            "x": 5,
            "y": 2,
            "z": -13,
            "elements": [
                "immersiveengineering:metal_decoration1@1"
            ]
        },
        {
            "x": 4,
            "y": 2,
            "z": -13,
            "nbt": {"conveyorBeltSubtypeNBT":{"dyeColour":"-1","direction":"0"},"facing":"5","conveyorBeltSubtype":"immersiveengineering:vertical","id":"immersiveengineering:conveyorbelt"},
            "elements": [
                "immersiveengineering:conveyor@0"
            ]
        },
        {
            "x": 21,
            "y": 1,
            "z": -13,
            "nbt": {"conveyorBeltSubtypeNBT":{"cover":{"id":"minecraft:air","Count":"1b","Damage":"0s"},"dyeColour":"-1","direction":"0"},"facing":"3","conveyorBeltSubtype":"immersiveengineering:covered","id":"immersiveengineering:conveyorbelt"},
            "elements": [
                "immersiveengineering:conveyor@0"
            ]
        },
        {
            "x": 15,
            "y": 1,
            "z": -13,
            "nbt": {"conveyorBeltSubtypeNBT":{"cover":{"id":"minecraft:air","Count":"1b","Damage":"0s"},"dyeColour":"-1","direction":"0"},"facing":"3","conveyorBeltSubtype":"immersiveengineering:covered","id":"immersiveengineering:conveyorbelt"},
            "elements": [
                "immersiveengineering:conveyor@0"
            ]
        },
        {
            "x": 9,
            "y": 1,
            "z": -13,
            "nbt": {"conveyorBeltSubtypeNBT":{"cover":{"id":"minecraft:air","Count":"1b","Damage":"0s"},"dyeColour":"-1","direction":"0"},"facing":"3","conveyorBeltSubtype":"immersiveengineering:covered","id":"immersiveengineering:conveyorbelt"},
            "elements": [
                "immersiveengineering:conveyor@0"
            ]
        },
        {
            "x": 5,
            "y": 1,
            "z": -13,
            "elements": [
                "immersiveengineering:metal_decoration1@1"
            ]
        },
        {
            "x": 4,
            "y": 1,
            "z": -13,
            "nbt": {"conveyorBeltSubtypeNBT":{"dyeColour":"-1","direction":"0"},"facing":"5","conveyorBeltSubtype":"immersiveengineering:vertical","id":"immersiveengineering:conveyorbelt"},
            "elements": [
                "immersiveengineering:conveyor@0"
            ]
        },
        {
            "x": 21,
            "y": 0,
            "z": -13,
            "elements": [
                "immersiveengineering:metal_decoration1@1"
            ]
        },
        {
            "x": 15,
            "y": 0,
            "z": -13,
            "elements": [
                "immersiveengineering:metal_decoration1@1"
            ]
        },
        {
            "x": 9,
            "y": 0,
            "z": -13,
            "elements": [
                "immersiveengineering:metal_decoration1@1"
            ]
        },
        {
            "x": 5,
            "y": 0,
            "z": -13,
            "elements": [
                "immersiveengineering:metal_decoration1@1"
            ]
        },
        {
            "x": 4,
            "y": 0,
            "z": -13,
            "nbt": {"conveyorBeltSubtypeNBT":{"dyeColour":"-1","direction":"0"},"facing":"5","conveyorBeltSubtype":"immersiveengineering:vertical","id":"immersiveengineering:conveyorbelt"},
            "elements": [
                "immersiveengineering:conveyor@0"
            ]
        },
        {
            "x": 21,
            "y": -1,
            "z": -13,
            "elements": [
                "immersiveengineering:metal_decoration1@1"
            ]
        },
        {
            "x": 15,
            "y": -1,
            "z": -13,
            "elements": [
                "immersiveengineering:metal_decoration1@1"
            ]
        },
        {
            "x": 9,
            "y": -1,
            "z": -13,
            "elements": [
                "immersiveengineering:metal_decoration1@1"
            ]
        },
        {
            "x": 5,
            "y": -1,
            "z": -13,
            "elements": [
                "immersiveengineering:metal_decoration1@1"
            ]
        },
        {
            "x": 4,
            "y": -1,
            "z": -13,
            "nbt": {"conveyorBeltSubtypeNBT":{"dyeColour":"-1","direction":"0"},"facing":"5","conveyorBeltSubtype":"immersiveengineering:vertical","id":"immersiveengineering:conveyorbelt"},
            "elements": [
                "immersiveengineering:conveyor@0"
            ]
        },
        {
            "x": 3,
            "y": -1,
            "z": -13,
            "nbt": {"conveyorBeltSubtypeNBT":{"dyeColour":"-1","direction":"0"},"facing":"5","conveyorBeltSubtype":"immersiveengineering:conveyor","id":"immersiveengineering:conveyorbelt"},
            "elements": [
                "immersiveengineering:conveyor@0"
            ]
        },
        {
            "x": 21,
            "y": 2,
            "z": -11,
            "nbt": {"conveyorBeltSubtypeNBT":{"cover":{"id":"minecraft:air","Count":"1b","Damage":"0s"},"dyeColour":"-1","direction":"1"},"facing":"3","conveyorBeltSubtype":"immersiveengineering:covered","id":"immersiveengineering:conveyorbelt"},
            "elements": [
                "immersiveengineering:conveyor@0"
            ]
        },
        {
            "x": 15,
            "y": 2,
            "z": -11,
            "nbt": {"conveyorBeltSubtypeNBT":{"cover":{"id":"minecraft:air","Count":"1b","Damage":"0s"},"dyeColour":"-1","direction":"1"},"facing":"3","conveyorBeltSubtype":"immersiveengineering:covered","id":"immersiveengineering:conveyorbelt"},
            "elements": [
                "immersiveengineering:conveyor@0"
            ]
        },
        {
            "x": 9,
            "y": 2,
            "z": -11,
            "nbt": {"conveyorBeltSubtypeNBT":{"cover":{"id":"minecraft:air","Count":"1b","Damage":"0s"},"dyeColour":"-1","direction":"1"},"facing":"3","conveyorBeltSubtype":"immersiveengineering:covered","id":"immersiveengineering:conveyorbelt"},
            "elements": [
                "immersiveengineering:conveyor@0"
            ]
        },
        {
            "x": 21,
            "y": 3,
            "z": -9,
            "nbt": {"conveyorBeltSubtypeNBT":{"cover":{"id":"minecraft:air","Count":"1b","Damage":"0s"},"dyeColour":"-1","direction":"0"},"facing":"3","conveyorBeltSubtype":"immersiveengineering:covered","id":"immersiveengineering:conveyorbelt"},
            "elements": [
                "immersiveengineering:conveyor@0"
            ]
        },
        {
            "x": 15,
            "y": 3,
            "z": -9,
            "nbt": {"conveyorBeltSubtypeNBT":{"cover":{"id":"minecraft:air","Count":"1b","Damage":"0s"},"dyeColour":"-1","direction":"0"},"facing":"3","conveyorBeltSubtype":"immersiveengineering:covered","id":"immersiveengineering:conveyorbelt"},
            "elements": [
                "immersiveengineering:conveyor@0"
            ]
        },
        {
            "x": 9,
            "y": 3,
            "z": -9,
            "nbt": {"conveyorBeltSubtypeNBT":{"cover":{"id":"minecraft:air","Count":"1b","Damage":"0s"},"dyeColour":"-1","direction":"0"},"facing":"3","conveyorBeltSubtype":"immersiveengineering:covered","id":"immersiveengineering:conveyorbelt"},
            "elements": [
                "immersiveengineering:conveyor@0"
            ]
        },
        {
            "x": 5,
            "y": 2,
            "z": -9,
            "elements": [
                "immersiveengineering:storage@8"
            ]
        },
        {
            "x": 4,
            "y": 2,
            "z": -9,
            "elements": [
                "immersiveengineering:storage@8"
            ]
        },
        {
            "x": 3,
            "y": 2,
            "z": -9,
            "elements": [
                "immersiveengineering:storage@8"
            ]
        },
        {
            "x": 5,
            "y": 1,
            "z": -9,
            "elements": [
                "immersiveengineering:storage@8"
            ]
        },
        {
            "x": 4,
            "y": 1,
            "z": -9,
            "elements": [
                "minecraft:glass@0"
            ]
        },
        {
            "x": 3,
            "y": 1,
            "z": -9,
            "elements": [
                "immersiveengineering:storage@8"
            ]
        },
        {
            "x": 5,
            "y": 0,
            "z": -9,
            "elements": [
                "immersiveengineering:storage@8"
            ]
        },
        {
            "x": 4,
            "y": 0,
            "z": -9,
            "nbt": {"id":"immersiveengineering:ieslab","slabType":"1"},
            "elements": [
                "immersiveengineering:sheetmetal_slab@8"
            ]
        },
        {
            "x": 3,
            "y": 0,
            "z": -9,
            "elements": [
                "immersiveengineering:storage@8"
            ]
        },
        {
            "x": 21,
            "y": 3,
            "z": -7,
            "nbt": {"conveyorBeltSubtypeNBT":{"cover":{"id":"minecraft:air","Count":"1b","Damage":"0s"},"dyeColour":"-1","direction":"0"},"facing":"3","conveyorBeltSubtype":"immersiveengineering:covered","id":"immersiveengineering:conveyorbelt"},
            "elements": [
                "immersiveengineering:conveyor@0"
            ]
        },
        {
            "x": 15,
            "y": 3,
            "z": -7,
            "nbt": {"conveyorBeltSubtypeNBT":{"cover":{"id":"minecraft:air","Count":"1b","Damage":"0s"},"dyeColour":"-1","direction":"0"},"facing":"3","conveyorBeltSubtype":"immersiveengineering:covered","id":"immersiveengineering:conveyorbelt"},
            "elements": [
                "immersiveengineering:conveyor@0"
            ]
        },
        {
            "x": 9,
            "y": 3,
            "z": -7,
            "nbt": {"conveyorBeltSubtypeNBT":{"cover":{"id":"minecraft:air","Count":"1b","Damage":"0s"},"dyeColour":"-1","direction":"0"},"facing":"3","conveyorBeltSubtype":"immersiveengineering:covered","id":"immersiveengineering:conveyorbelt"},
            "elements": [
                "immersiveengineering:conveyor@0"
            ]
        },
        {
            "x": 5,
            "y": -1,
            "z": -9,
            "elements": [
                "immersiveengineering:storage@8"
            ]
        },
        {
            "x": 4,
            "y": -1,
            "z": -9,
            "nbt": {"id":"immersiveengineering:ieslab","slabType":"0"},
            "elements": [
                "immersiveengineering:sheetmetal_slab@8"
            ]
        },
        {
            "x": 3,
            "y": -1,
            "z": -9,
            "elements": [
                "immersiveengineering:storage@8"
            ]
        },
        {
            "x": 23,
            "y": 2,
            "z": -7,
            "elements": [
                "immersiveengineering:storage@8"
            ]
        },
        {
            "x": 22,
            "y": 2,
            "z": -7,
            "elements": [
                "immersiveengineering:sheetmetal@8"
            ]
        },
        {
            "x": 21,
            "y": 2,
            "z": -7,
            "elements": [
                "immersiveengineering:sheetmetal@8"
            ]
        },
        {
            "x": 20,
            "y": 2,
            "z": -7,
            "elements": [
                "immersiveengineering:sheetmetal@8"
            ]
        },
        {
            "x": 19,
            "y": 2,
            "z": -7,
            "elements": [
                "immersiveengineering:sheetmetal@8"
            ]
        },
        {
            "x": 18,
            "y": 2,
            "z": -7,
            "elements": [
                "immersiveengineering:sheetmetal@8"
            ]
        },
        {
            "x": 17,
            "y": 2,
            "z": -7,
            "elements": [
                "immersiveengineering:sheetmetal@8"
            ]
        },
        {
            "x": 16,
            "y": 2,
            "z": -7,
            "elements": [
                "immersiveengineering:sheetmetal@8"
            ]
        },
        {
            "x": 15,
            "y": 2,
            "z": -7,
            "elements": [
                "immersiveengineering:sheetmetal@8"
            ]
        },
        {
            "x": 14,
            "y": 2,
            "z": -7,
            "elements": [
                "immersiveengineering:sheetmetal@8"
            ]
        },
        {
            "x": 13,
            "y": 2,
            "z": -7,
            "elements": [
                "immersiveengineering:sheetmetal@8"
            ]
        },
        {
            "x": 12,
            "y": 2,
            "z": -7,
            "elements": [
                "immersiveengineering:sheetmetal@8"
            ]
        },
        {
            "x": 11,
            "y": 2,
            "z": -7,
            "elements": [
                "immersiveengineering:sheetmetal@8"
            ]
        },
        {
            "x": 10,
            "y": 2,
            "z": -7,
            "elements": [
                "immersiveengineering:sheetmetal@8"
            ]
        },
        {
            "x": 9,
            "y": 2,
            "z": -7,
            "elements": [
                "immersiveengineering:sheetmetal@8"
            ]
        },
        {
            "x": 8,
            "y": 2,
            "z": -7,
            "elements": [
                "immersiveengineering:sheetmetal@8"
            ]
        },
        {
            "x": 7,
            "y": 2,
            "z": -7,
            "elements": [
                "immersiveengineering:storage@8"
            ]
        },
        {
            "x": 5,
            "y": 2,
            "z": -7,
            "elements": [
                "immersiveengineering:storage@8"
            ]
        },
        {
            "x": 3,
            "y": 2,
            "z": -7,
            "elements": [
                "immersiveengineering:storage@8"
            ]
        },
        {
            "x": 23,
            "y": 1,
            "z": -7,
            "elements": [
                "immersiveengineering:storage@8"
            ]
        },
        {
            "x": 22,
            "y": 1,
            "z": -7,
            "elements": [
                "immersiveengineering:sheetmetal@8"
            ]
        },
        {
            "x": 21,
            "y": 1,
            "z": -7,
            "elements": [
                "immersiveengineering:sheetmetal@8"
            ]
        },
        {
            "x": 20,
            "y": 1,
            "z": -7,
            "elements": [
                "immersiveengineering:sheetmetal@8"
            ]
        },
        {
            "x": 19,
            "y": 1,
            "z": -7,
            "elements": [
                "immersiveengineering:sheetmetal@8"
            ]
        },
        {
            "x": 18,
            "y": 1,
            "z": -7,
            "elements": [
                "immersiveengineering:sheetmetal@8"
            ]
        },
        {
            "x": 17,
            "y": 1,
            "z": -7,
            "elements": [
                "immersiveengineering:sheetmetal@8"
            ]
        },
        {
            "x": 16,
            "y": 1,
            "z": -7,
            "elements": [
                "immersiveengineering:sheetmetal@8"
            ]
        },
        {
            "x": 15,
            "y": 1,
            "z": -7,
            "elements": [
                "immersiveengineering:sheetmetal@8"
            ]
        },
        {
            "x": 14,
            "y": 1,
            "z": -7,
            "elements": [
                "immersiveengineering:sheetmetal@8"
            ]
        },
        {
            "x": 13,
            "y": 1,
            "z": -7,
            "elements": [
                "immersiveengineering:sheetmetal@8"
            ]
        },
        {
            "x": 12,
            "y": 1,
            "z": -7,
            "elements": [
                "immersiveengineering:sheetmetal@8"
            ]
        },
        {
            "x": 11,
            "y": 1,
            "z": -7,
            "elements": [
                "immersiveengineering:sheetmetal@8"
            ]
        },
        {
            "x": 10,
            "y": 1,
            "z": -7,
            "elements": [
                "immersiveengineering:sheetmetal@8"
            ]
        },
        {
            "x": 9,
            "y": 1,
            "z": -7,
            "elements": [
                "immersiveengineering:sheetmetal@8"
            ]
        },
        {
            "x": 8,
            "y": 1,
            "z": -7,
            "elements": [
                "immersiveengineering:sheetmetal@8"
            ]
        },
        {
            "x": 7,
            "y": 1,
            "z": -7,
            "elements": [
                "immersiveengineering:storage@8"
            ]
        },
        {
            "x": 5,
            "y": 1,
            "z": -7,
            "elements": [
                "minecraft:glass@0"
            ]
        },
        {
            "x": 4,
            "y": 1,
            "z": -7,
            "nbt": {"conveyorBeltSubtypeNBT":{"dyeColour":"-1","direction":"0"},"facing":"2","conveyorBeltSubtype":"immersiveengineering:dropper","id":"immersiveengineering:conveyorbelt"},
            "elements": [
                "immersiveengineering:conveyor@0"
            ]
        },
        {
            "x": 3,
            "y": 1,
            "z": -7,
            "elements": [
                "minecraft:glass@0"
            ]
        },
        {
            "x": 23,
            "y": 0,
            "z": -7,
            "elements": [
                "immersiveengineering:storage@8"
            ]
        },
        {
            "x": 22,
            "y": 0,
            "z": -7,
            "elements": [
                "immersiveengineering:sheetmetal@8"
            ]
        },
        {
            "x": 21,
            "y": 0,
            "z": -7,
            "elements": [
                "immersiveengineering:sheetmetal@8"
            ]
        },
        {
            "x": 20,
            "y": 0,
            "z": -7,
            "elements": [
                "immersiveengineering:sheetmetal@8"
            ]
        },
        {
            "x": 19,
            "y": 0,
            "z": -7,
            "elements": [
                "immersiveengineering:sheetmetal@8"
            ]
        },
        {
            "x": 18,
            "y": 0,
            "z": -7,
            "elements": [
                "immersiveengineering:sheetmetal@8"
            ]
        },
        {
            "x": 17,
            "y": 0,
            "z": -7,
            "elements": [
                "immersiveengineering:sheetmetal@8"
            ]
        },
        {
            "x": 16,
            "y": 0,
            "z": -7,
            "elements": [
                "immersiveengineering:sheetmetal@8"
            ]
        },
        {
            "x": 15,
            "y": 0,
            "z": -7,
            "elements": [
                "immersiveengineering:sheetmetal@8"
            ]
        },
        {
            "x": 14,
            "y": 0,
            "z": -7,
            "elements": [
                "immersiveengineering:sheetmetal@8"
            ]
        },
        {
            "x": 13,
            "y": 0,
            "z": -7,
            "elements": [
                "immersiveengineering:sheetmetal@8"
            ]
        },
        {
            "x": 12,
            "y": 0,
            "z": -7,
            "elements": [
                "immersiveengineering:sheetmetal@8"
            ]
        },
        {
            "x": 11,
            "y": 0,
            "z": -7,
            "elements": [
                "immersiveengineering:sheetmetal@8"
            ]
        },
        {
            "x": 10,
            "y": 0,
            "z": -7,
            "elements": [
                "immersiveengineering:sheetmetal@8"
            ]
        },
        {
            "x": 9,
            "y": 0,
            "z": -7,
            "elements": [
                "immersiveengineering:sheetmetal@8"
            ]
        },
        {
            "x": 8,
            "y": 0,
            "z": -7,
            "elements": [
                "immersiveengineering:sheetmetal@8"
            ]
        },
        {
            "x": 7,
            "y": 0,
            "z": -7,
            "elements": [
                "immersiveengineering:storage@8"
            ]
        },
        {
            "x": 5,
            "y": 0,
            "z": -7,
            "nbt": {"id":"immersiveengineering:ieslab","slabType":"1"},
            "elements": [
                "immersiveengineering:sheetmetal_slab@8"
            ]
        },
        {
            "x": 4,
            "y": 0,
            "z": -7,

            "elements": [
                "minecraft:hopper@0"
            ]
        },
        {
            "x": 3,
            "y": 0,
            "z": -7,
            "nbt": {"id":"immersiveengineering:ieslab","slabType":"1"},
            "elements": [
                "immersiveengineering:sheetmetal_slab@8"
            ]
        },
        {
            "x": 21,
            "y": 6,
            "z": -20,
            "nbt": {"conveyorBeltSubtypeNBT":{"cover":{"id":"minecraft:air","Count":"1b","Damage":"0s"},"dyeColour":"-1","direction":"0"},"facing":"2","conveyorBeltSubtype":"immersiveengineering:droppercovered","id":"immersiveengineering:conveyorbelt"},
            "elements": [
                "immersiveengineering:conveyor@0"
            ]
        },
        {
            "x": 15,
            "y": 6,
            "z": -20,
            "nbt": {"conveyorBeltSubtypeNBT":{"cover":{"id":"minecraft:air","Count":"1b","Damage":"0s"},"dyeColour":"-1","direction":"0"},"facing":"2","conveyorBeltSubtype":"immersiveengineering:droppercovered","id":"immersiveengineering:conveyorbelt"},
            "elements": [
                "immersiveengineering:conveyor@0"
            ]
        },
        {
            "x": 23,
            "y": -1,
            "z": -7,
            "elements": [
                "immersiveengineering:storage@8"
            ]
        },
        {
            "x": 22,
            "y": -1,
            "z": -7,
            "nbt": {"casingColor":"16730368","id":"minecraft:tilecolorablemachinecomponent"},
            "elements": [
                "modularmachinery:blockcasing@0"
            ]
        },
        {
            "x": 9,
            "y": 6,
            "z": -20,
            "nbt": {"conveyorBeltSubtypeNBT":{"cover":{"id":"minecraft:air","Count":"1b","Damage":"0s"},"dyeColour":"-1","direction":"0"},"facing":"5","conveyorBeltSubtype":"immersiveengineering:droppercovered","id":"immersiveengineering:conveyorbelt"},
            "elements": [
                "immersiveengineering:conveyor@0"
            ]
        },
        {
            "x": 21,
            "y": -1,
            "z": -7,
            "nbt": {"casingColor":"16730368","id":"minecraft:tilecolorablemachinecomponent"},
            "elements": [
                "modularmachinery:blockcasing@0"
            ]
        },
        {
            "x": 8,
            "y": 6,
            "z": -20,
            "nbt": {"conveyorBeltSubtypeNBT":{"cover":{"id":"minecraft:air","Count":"1b","Damage":"0s"},"dyeColour":"-1","direction":"0"},"facing":"5","conveyorBeltSubtype":"immersiveengineering:covered","id":"immersiveengineering:conveyorbelt"},
            "elements": [
                "immersiveengineering:conveyor@0"
            ]
        },
        {
            "x": 20,
            "y": -1,
            "z": -7,
            "nbt": {"casingColor":"16730368","id":"minecraft:tilecolorablemachinecomponent"},
            "elements": [
                "modularmachinery:blockcasing@0"
            ]
        },
        {
            "x": 19,
            "y": -1,
            "z": -7,
            "nbt": {"casingColor":"16730368","id":"minecraft:tilecolorablemachinecomponent"},
            "elements": [
                "modularmachinery:blockcasing@0"
            ]
        },
        {
            "x": 18,
            "y": -1,
            "z": -7,
            "nbt": {"casingColor":"16730368","id":"minecraft:tilecolorablemachinecomponent"},
            "elements": [
                "modularmachinery:blockcasing@0"
            ]
        },
        {
            "x": 17,
            "y": -1,
            "z": -7,
            "nbt": {"casingColor":"16730368","id":"minecraft:tilecolorablemachinecomponent"},
            "elements": [
                "modularmachinery:blockcasing@0"
            ]
        },
        {
            "x": 16,
            "y": -1,
            "z": -7,
            "nbt": {"casingColor":"16730368","id":"minecraft:tilecolorablemachinecomponent"},
            "elements": [
                "modularmachinery:blockcasing@0"
            ]
        },
        {
            "x": 15,
            "y": -1,
            "z": -7,
            "nbt": {"casingColor":"16730368","id":"minecraft:tilecolorablemachinecomponent"},
            "elements": [
                "modularmachinery:blockcasing@0"
            ]
        },
        {
            "x": 14,
            "y": -1,
            "z": -7,
            "nbt": {"casingColor":"16730368","id":"minecraft:tilecolorablemachinecomponent"},
            "elements": [
                "modularmachinery:blockcasing@0"
            ]
        },
        {
            "x": 13,
            "y": -1,
            "z": -7,
            "nbt": {"casingColor":"16730368","id":"minecraft:tilecolorablemachinecomponent"},
            "elements": [
                "modularmachinery:blockcasing@0"
            ]
        },
        {
            "x": 12,
            "y": -1,
            "z": -7,
            "nbt": {"casingColor":"16730368","id":"minecraft:tilecolorablemachinecomponent"},
            "elements": [
                "modularmachinery:blockcasing@0"
            ]
        },
        {
            "x": 11,
            "y": -1,
            "z": -7,
            "nbt": {"casingColor":"16730368","id":"minecraft:tilecolorablemachinecomponent"},
            "elements": [
                "modularmachinery:blockcasing@0"
            ]
        },
        {
            "x": 10,
            "y": -1,
            "z": -7,
            "nbt": {"casingColor":"16730368","id":"minecraft:tilecolorablemachinecomponent"},
            "elements": [
                "modularmachinery:blockcasing@0"
            ]
        },
        {
            "x": 9,
            "y": -1,
            "z": -7,
            "nbt": {"casingColor":"16730368","id":"minecraft:tilecolorablemachinecomponent"},
            "elements": [
                "modularmachinery:blockcasing@0"
            ]
        },
        {
            "x": 8,
            "y": -1,
            "z": -7,
            "nbt": {"casingColor":"16730368","id":"minecraft:tilecolorablemachinecomponent"},
            "elements": [
                "modularmachinery:blockcasing@0"
            ]
        },
        {
            "x": 7,
            "y": -1,
            "z": -7,
            "elements": [
                "immersiveengineering:storage@8"
            ]
        },
        {
            "x": 5,
            "y": -1,
            "z": -7,
            "nbt": {"id":"immersiveengineering:ieslab","slabType":"0"},
            "elements": [
                "immersiveengineering:sheetmetal_slab@8"
            ]
        },
        {
            "x": 4,
            "y": -1,
            "z": -7,
            "nbt": {"busSize":"1","casingColor":"16730368","id":"minecraft:tileiteminputbus"}, 
            "elements": [
                "modularmachinery:blockinputbus@1"
            ]
        },
        {
            "x": 22,
            "y": 5,
            "z": -20,
            "elements": [
                "immersiveengineering:metal_multiblock"
            ]
        },
        {
            "x": 3,
            "y": -1,
            "z": -7,
            "nbt": {"id":"immersiveengineering:ieslab","slabType":"0"},
            "elements": [
                "immersiveengineering:sheetmetal_slab@8"
            ]
        },
        {
            "x": 21,
            "y": 5,
            "z": -20,
            "elements": [
                "immersiveengineering:metal_multiblock"
            ]
        },
        {
            "x": 20,
            "y": 5,
            "z": -20,
            "elements": [
                "immersiveengineering:metal_multiblock"
            ]
        },
        {
            "x": 16,
            "y": 5,
            "z": -20,
            "elements": [
                "immersiveengineering:metal_multiblock"
            ]
        },
        {
            "x": 15,
            "y": 5,
            "z": -20,
            "elements": [
                "immersiveengineering:metal_multiblock"
            ]
        },
        {
            "x": 14,
            "y": 5,
            "z": -20,
            "elements": [
                "immersiveengineering:metal_multiblock"
            ]
        },
        {
            "x": 10,
            "y": 5,
            "z": -20,
            "elements": [
                "immersiveengineering:metal_multiblock"
            ]
        },
        {
            "x": 9,
            "y": 5,
            "z": -20,
            "elements": [
                "immersiveengineering:metal_multiblock"
            ]
        },
        {
            "x": 23,
            "y": 2,
            "z": -5,
            "elements": [
                "immersiveengineering:sheetmetal@8"
            ]
        },
        {
            "x": 8,
            "y": 5,
            "z": -20,
            "elements": [
                "immersiveengineering:metal_multiblock"
            ]
        },
        {
            "x": 7,
            "y": 5,
            "z": -20,
            "nbt": {"conveyorBeltSubtypeNBT":{"cover":{"id":"minecraft:air","Count":"1b","Damage":"0s"},"dyeColour":"-1","direction":"1"},"facing":"5","conveyorBeltSubtype":"immersiveengineering:covered","id":"immersiveengineering:conveyorbelt"},
            "elements": [
                "immersiveengineering:conveyor@0"
            ]
        },
        {
            "x": 7,
            "y": 2,
            "z": -5,
            "elements": [
                "immersiveengineering:sheetmetal@8"
            ]
        },
        {
            "x": 22,
            "y": 4,
            "z": -20,
            "elements": [
                "immersiveengineering:metal_multiblock"
            ]
        },
        {
            "x": 5,
            "y": 2,
            "z": -5,
            "elements": [
                "immersiveengineering:storage@8"
            ]
        },
        {
            "x": 20,
            "y": 4,
            "z": -20,
            "elements": [
                "immersiveengineering:metal_multiblock"
            ]
        },
        {
            "x": 3,
            "y": 2,
            "z": -5,
            "elements": [
                "immersiveengineering:storage@8"
            ]
        },
        {
            "x": 16,
            "y": 4,
            "z": -20,
            "elements": [
                "immersiveengineering:metal_multiblock"
            ]
        },
        {
            "x": 14,
            "y": 4,
            "z": -20,
            "elements": [
                "immersiveengineering:metal_multiblock"
            ]
        },
        {
            "x": 10,
            "y": 4,
            "z": -20,
            "elements": [
                "immersiveengineering:metal_multiblock"
            ]
        },
        {
            "x": 23,
            "y": 1,
            "z": -5,
            "elements": [
                "immersiveengineering:sheetmetal@8"
            ]
        },
        {
            "x": 8,
            "y": 4,
            "z": -20,
            "elements": [
                "immersiveengineering:metal_multiblock"
            ]
        },
        {
            "x": 6,
            "y": 4,
            "z": -20,
            "nbt": {"conveyorBeltSubtypeNBT":{"cover":{"id":"minecraft:air","Count":"1b","Damage":"0s"},"dyeColour":"-1","direction":"1"},"facing":"5","conveyorBeltSubtype":"immersiveengineering:covered","id":"immersiveengineering:conveyorbelt"},
            "elements": [
                "immersiveengineering:conveyor@0"
            ]
        },
        {
            "x": 5,
            "y": 4,
            "z": -20,
            "nbt": {"conveyorBeltSubtypeNBT":{"cover":{"id":"minecraft:air","Count":"1b","Damage":"0s"},"dyeColour":"-1","direction":"0"},"facing":"5","conveyorBeltSubtype":"immersiveengineering:covered","id":"immersiveengineering:conveyorbelt"},
            "elements": [
                "immersiveengineering:conveyor@0"
            ]
        },
        {
            "x": 7,
            "y": 1,
            "z": -5,
            "elements": [
                "immersiveengineering:sheetmetal@8"
            ]
        },
        {
            "x": 22,
            "y": 3,
            "z": -20,
            "elements": [
                "immersiveengineering:metal_multiblock"
            ]
        },
        {
            "x": 5,
            "y": 1,
            "z": -5,
            "elements": [
                "minecraft:glass@0"
            ]
        },
        {
            "x": 4,
            "y": 1,
            "z": -5,
            "nbt": {"conveyorBeltSubtypeNBT":{"dyeColour":"-1","direction":"0"},"facing":"2","conveyorBeltSubtype":"immersiveengineering:dropper","id":"immersiveengineering:conveyorbelt"},
            "elements": [
                "immersiveengineering:conveyor@0"
            ]
        },
        {
            "x": 20,
            "y": 3,
            "z": -20,
            "elements": [
                "immersiveengineering:metal_multiblock"
            ]
        },
        {
            "x": 3,
            "y": 1,
            "z": -5,
            "elements": [
                "minecraft:glass@0"
            ]
        },
        {
            "x": 16,
            "y": 3,
            "z": -20,
            "elements": [
                "immersiveengineering:metal_multiblock"
            ]
        },
        {
            "x": 14,
            "y": 3,
            "z": -20,
            "elements": [
                "immersiveengineering:metal_multiblock"
            ]
        },
        {
            "x": 10,
            "y": 3,
            "z": -20,
            "elements": [
                "immersiveengineering:metal_multiblock"
            ]
        },
        {
            "x": 23,
            "y": 0,
            "z": -5,
            "elements": [
                "immersiveengineering:sheetmetal@8"
            ]
        },
        {
            "x": 8,
            "y": 3,
            "z": -20,
            "elements": [
                "immersiveengineering:metal_multiblock"
            ]
        },
        {
            "x": 5,
            "y": 3,
            "z": -20,
            "elements": [
                "immersiveengineering:metal_decoration1@1"
            ]
        },
        {
            "x": 4,
            "y": 3,
            "z": -20,
            "nbt": {"conveyorBeltSubtypeNBT":{"dyeColour":"-1","direction":"0"},"facing":"5","conveyorBeltSubtype":"immersiveengineering:vertical","id":"immersiveengineering:conveyorbelt"},
            "elements": [
                "immersiveengineering:conveyor@0"
            ]
        },
        {
            "x": 7,
            "y": 0,
            "z": -5,
            "elements": [
                "immersiveengineering:sheetmetal@8"
            ]
        },
        {
            "x": 22,
            "y": 2,
            "z": -20,
            "elements": [
                "immersiveengineering:metal_multiblock"
            ]
        },
        {
            "x": 5,
            "y": 0,
            "z": -5,
            "nbt": {"id":"immersiveengineering:ieslab","slabType":"1"},
            "elements": [
                "immersiveengineering:sheetmetal_slab@8"
            ]
        },
        {
            "x": 4,
            "y": 0,
            "z": -5,

            "elements": [
                "minecraft:hopper@0"
            ]
        },
        {
            "x": 20,
            "y": 2,
            "z": -20,
            "elements": [
                "immersiveengineering:metal_multiblock"
            ]
        },
        {
            "x": 3,
            "y": 0,
            "z": -5,
            "nbt": {"id":"immersiveengineering:ieslab","slabType":"1"},
            "elements": [
                "immersiveengineering:sheetmetal_slab@8"
            ]
        },
        {
            "x": 16,
            "y": 2,
            "z": -20,
            "elements": [
                "immersiveengineering:metal_multiblock"
            ]
        },
        {
            "x": 14,
            "y": 2,
            "z": -20,
            "elements": [
                "immersiveengineering:metal_multiblock"
            ]
        },
        {
            "x": 10,
            "y": 2,
            "z": -20,
            "elements": [
                "immersiveengineering:metal_multiblock"
            ]
        },
        {
            "x": 23,
            "y": -1,
            "z": -5,
            "elements": [
                "immersiveengineering:sheetmetal@8"
            ]
        },
        {
            "x": 8,
            "y": 2,
            "z": -20,
            "elements": [
                "immersiveengineering:metal_multiblock"
            ]
        },
        {
            "x": 22,
            "y": -1,
            "z": -5,
            "elements": [
                "immersiveengineering:sheetmetal@8"
            ]
        },
        {
            "x": 21,
            "y": -1,
            "z": -5,
            "elements": [
                "immersiveengineering:sheetmetal@8"
            ]
        },
        {
            "x": 20,
            "y": -1,
            "z": -5,
            "elements": [
                "immersiveengineering:sheetmetal@8"
            ]
        },
        {
            "x": 5,
            "y": 2,
            "z": -20,
            "elements": [
                "immersiveengineering:metal_decoration1@1"
            ]
        },
        {
            "x": 19,
            "y": -1,
            "z": -5,
            "elements": [
                "immersiveengineering:sheetmetal@8"
            ]
        },
        {
            "x": 4,
            "y": 2,
            "z": -20,
            "nbt": {"conveyorBeltSubtypeNBT":{"dyeColour":"-1","direction":"0"},"facing":"5","conveyorBeltSubtype":"immersiveengineering:vertical","id":"immersiveengineering:conveyorbelt"},
            "elements": [
                "immersiveengineering:conveyor@0"
            ]
        },
        {
            "x": 18,
            "y": -1,
            "z": -5,
            "elements": [
                "immersiveengineering:sheetmetal@8"
            ]
        },
        {
            "x": 17,
            "y": -1,
            "z": -5,
            "elements": [
                "immersiveengineering:sheetmetal@8"
            ]
        },
        {
            "x": 16,
            "y": -1,
            "z": -5,
            "elements": [
                "immersiveengineering:sheetmetal@8"
            ]
        },
        {
            "x": 15,
            "y": -1,
            "z": -5,
            "nbt": {"conveyorBeltSubtypeNBT":{"dyeColour":"-1","direction":"0"},"facing":"3","conveyorBeltSubtype":"immersiveengineering:conveyor","id":"immersiveengineering:conveyorbelt"},
            "elements": [
                "immersiveengineering:conveyor@0"
            ]
        },
        {
            "x": 14,
            "y": -1,
            "z": -5,
            "elements": [
                "immersiveengineering:sheetmetal@8"
            ]
        },
        {
            "x": 13,
            "y": -1,
            "z": -5,
            "elements": [
                "immersiveengineering:sheetmetal@8"
            ]
        },
        {
            "x": 12,
            "y": -1,
            "z": -5,
            "elements": [
                "immersiveengineering:sheetmetal@8"
            ]
        },
        {
            "x": 11,
            "y": -1,
            "z": -5,
            "elements": [
                "immersiveengineering:sheetmetal@8"
            ]
        },
        {
            "x": 10,
            "y": -1,
            "z": -5,
            "elements": [
                "immersiveengineering:sheetmetal@8"
            ]
        },
        {
            "x": 9,
            "y": -1,
            "z": -5,
            "elements": [
                "immersiveengineering:sheetmetal@8"
            ]
        },
        {
            "x": 8,
            "y": -1,
            "z": -5,
            "elements": [
                "immersiveengineering:sheetmetal@8"
            ]
        },
        {
            "x": 7,
            "y": -1,
            "z": -5,
            "elements": [
                "immersiveengineering:sheetmetal@8"
            ]
        },
        {
            "x": 22,
            "y": 1,
            "z": -20,
            "elements": [
                "immersiveengineering:metal_multiblock"
            ]
        },
        {
            "x": 5,
            "y": -1,
            "z": -5,
            "nbt": {"id":"immersiveengineering:ieslab","slabType":"0"},
            "elements": [
                "immersiveengineering:sheetmetal_slab@8"
            ]
        },
        {
            "x": 4,
            "y": -1,
            "z": -5,
            "nbt": {"busSize":"1","casingColor":"16730368","id":"minecraft:tileiteminputbus"},
            "elements": [
                "modularmachinery:blockinputbus@1"
            ]
        },
        {
            "x": 20,
            "y": 1,
            "z": -20,
            "elements": [
                "immersiveengineering:metal_multiblock"
            ]
        },
        {
            "x": 3,
            "y": -1,
            "z": -5,
            "nbt": {"id":"immersiveengineering:ieslab","slabType":"0"},
            "elements": [
                "immersiveengineering:sheetmetal_slab@8"
            ]
        },
        {
            "x": 21,
            "y": 5,
            "z": -18,
            "nbt": {"conveyorBeltSubtypeNBT":{"cover":{"id":"minecraft:air","Count":"1b","Damage":"0s"},"dyeColour":"-1","direction":"1"},"facing":"2","conveyorBeltSubtype":"immersiveengineering:covered","id":"immersiveengineering:conveyorbelt"},
            "elements": [
                "immersiveengineering:conveyor@0"
            ]
        },
        {
            "x": 16,
            "y": 1,
            "z": -20,
            "elements": [
                "immersiveengineering:metal_multiblock"
            ]
        },
        {
            "x": 14,
            "y": 1,
            "z": -20,
            "elements": [
                "immersiveengineering:metal_multiblock"
            ]
        },
        {
            "x": 15,
            "y": 5,
            "z": -18,
            "nbt": {"conveyorBeltSubtypeNBT":{"cover":{"id":"minecraft:air","Count":"1b","Damage":"0s"},"dyeColour":"-1","direction":"1"},"facing":"2","conveyorBeltSubtype":"immersiveengineering:covered","id":"immersiveengineering:conveyorbelt"},
            "elements": [
                "immersiveengineering:conveyor@0"
            ]
        },
        {
            "x": 10,
            "y": 1,
            "z": -20,
            "elements": [
                "immersiveengineering:metal_multiblock"
            ]
        },
        {
            "x": 8,
            "y": 1,
            "z": -20,
            "elements": [
                "immersiveengineering:metal_multiblock"
            ]
        },
        {
            "x": 23,
            "y": 2,
            "z": -3,
            "elements": [
                "immersiveengineering:sheetmetal@8"
            ]
        },
        {
            "x": 5,
            "y": 1,
            "z": -20,
            "elements": [
                "immersiveengineering:metal_decoration1@1"
            ]
        },
        {
            "x": 4,
            "y": 1,
            "z": -20,
            "nbt": {"conveyorBeltSubtypeNBT":{"dyeColour":"-1","direction":"0"},"facing":"5","conveyorBeltSubtype":"immersiveengineering:vertical","id":"immersiveengineering:conveyorbelt"},
            "elements": [
                "immersiveengineering:conveyor@0"
            ]
        },
        {
            "x": 22,
            "y": 0,
            "z": -20,
            "elements": [
                "immersiveengineering:metal_multiblock"
            ]
        },
        {
            "x": 7,
            "y": 2,
            "z": -3,
            "elements": [
                "immersiveengineering:sheetmetal@8"
            ]
        },
        {
            "x": 20,
            "y": 0,
            "z": -20,
            "elements": [
                "immersiveengineering:metal_multiblock"
            ]
        },
        {
            "x": 5,
            "y": 2,
            "z": -3,
            "elements": [
                "immersiveengineering:storage@8"
            ]
        },
        {
            "x": 3,
            "y": 2,
            "z": -3,
            "elements": [
                "immersiveengineering:storage@8"
            ]
        },
        {
            "x": 16,
            "y": 0,
            "z": -20,
            "elements": [
                "immersiveengineering:metal_multiblock"
            ]
        },
        {
            "x": 14,
            "y": 0,
            "z": -20,
            "elements": [
                "immersiveengineering:metal_multiblock"
            ]
        },
        {
            "x": 10,
            "y": 0,
            "z": -20,
            "elements": [
                "immersiveengineering:metal_multiblock"
            ]
        },
        {
            "x": 8,
            "y": 0,
            "z": -20,
            "elements": [
                "immersiveengineering:metal_multiblock"
            ]
        },
        {
            "x": 23,
            "y": 1,
            "z": -3,
            "elements": [
                "immersiveengineering:sheetmetal@8"
            ]
        },
        {
            "x": 5,
            "y": 0,
            "z": -20,
            "elements": [
                "immersiveengineering:metal_decoration1@1"
            ]
        },
        {
            "x": 4,
            "y": 0,
            "z": -20,
            "nbt": {"conveyorBeltSubtypeNBT":{"dyeColour":"-1","direction":"0"},"facing":"5","conveyorBeltSubtype":"immersiveengineering:vertical","id":"immersiveengineering:conveyorbelt"},
            "elements": [
                "immersiveengineering:conveyor@0"
            ]
        },
        {
            "x": -10,
            "y": -1,
            "z": 3,
            "elements": [
                "immersiveengineering:metal_multiblock"
            ]
        },
        {
            "x": 7,
            "y": 1,
            "z": -3,
            "elements": [
                "immersiveengineering:sheetmetal@8"
            ]
        },
        {
            "x": -8,
            "y": -1,
            "z": 3,
            "elements": [
                "immersiveengineering:metal_multiblock"
            ]
        },
        {
            "x": 21,
            "y": -1,
            "z": -20,
            "elements": [
                "immersiveengineering:metal_multiblock"
            ]
        },
        {
            "x": 5,
            "y": 1,
            "z": -3,
            "elements": [
                "minecraft:glass@0"
            ]
        },
        {
            "x": 4,
            "y": 1,
            "z": -3,
            "nbt": {"conveyorBeltSubtypeNBT":{"dyeColour":"-1","direction":"0"},"facing":"2","conveyorBeltSubtype":"immersiveengineering:dropper","id":"immersiveengineering:conveyorbelt"},
            "elements": [
                "immersiveengineering:conveyor@0"
            ]
        },
        {
            "x": 3,
            "y": 1,
            "z": -3,
            "elements": [
                "minecraft:glass@0"
            ]
        },
        {
            "x": 15,
            "y": -1,
            "z": -20,
            "elements": [
                "immersiveengineering:metal_multiblock"
            ]
        },
        {
            "x": 9,
            "y": -1,
            "z": -20,
            "elements": [
                "immersiveengineering:metal_multiblock"
            ]
        },
        {
            "x": 23,
            "y": 0,
            "z": -3,
            "elements": [
                "immersiveengineering:sheetmetal@8"
            ]
        },
        {
            "x": 22,
            "y": 0,
            "z": -3,
            "elements": [
                "minecraft:water@0"
            ]
        },
        {
            "x": 5,
            "y": -1,
            "z": -20,
            "elements": [
                "immersiveengineering:metal_decoration1@1"
            ]
        },
        {
            "x": 4,
            "y": -1,
            "z": -20,
            "nbt": {"conveyorBeltSubtypeNBT":{"dyeColour":"-1","direction":"0"},"facing":"5","conveyorBeltSubtype":"immersiveengineering:vertical","id":"immersiveengineering:conveyorbelt"},
            "elements": [
                "immersiveengineering:conveyor@0"
            ]
        },
        {
            "x": 3,
            "y": -1,
            "z": -20,
            "nbt": {"conveyorBeltSubtypeNBT":{"dyeColour":"-1","direction":"0"},"facing":"5","conveyorBeltSubtype":"immersiveengineering:conveyor","id":"immersiveengineering:conveyorbelt"},
            "elements": [
                "immersiveengineering:conveyor@0"
            ]
        },
        {
            "x": 15,
            "y": 0,
            "z": -3,
            "nbt": {"id":"immersiveengineering:ieslab","slabType":"0"},
            "elements": [
                "immersiveengineering:sheetmetal_slab@8"
            ]
        },
        {
            "x": -10,
            "y": 0,
            "z": 3,
            "elements": [
                "immersiveengineering:metal_multiblock"
            ]
        },
        {
            "x": -9,
            "y": 0,
            "z": 3,
            "elements": [
                "immersiveengineering:metal_multiblock"
            ]
        },
        {
            "x": 8,
            "y": 0,
            "z": -3,
            "elements": [
                "minecraft:water@0"
            ]
        },
        {
            "x": 7,
            "y": 0,
            "z": -3,
            "elements": [
                "immersiveengineering:sheetmetal@8"
            ]
        },
        {
            "x": -8,
            "y": 0,
            "z": 3,
            "elements": [
                "immersiveengineering:metal_multiblock"
            ]
        },
        {
            "x": 5,
            "y": 0,
            "z": -3,
            "nbt": {"id":"immersiveengineering:ieslab","slabType":"1"},
            "elements": [
                "immersiveengineering:sheetmetal_slab@8"
            ]
        },
        {
            "x": 4,
            "y": 0,
            "z": -3,

            "elements": [
                "minecraft:hopper@0"
            ]
        },
        {
            "x": 3,
            "y": 0,
            "z": -3,
            "nbt": {"id":"immersiveengineering:ieslab","slabType":"1"},
            "elements": [
                "immersiveengineering:sheetmetal_slab@8"
            ]
        },
        {
            "x": 23,
            "y": -1,
            "z": -3,
            "elements": [
                "immersiveengineering:sheetmetal@8"
            ]
        },
        {
            "x": 22,
            "y": -1,
            "z": -3,
            "elements": [
                "immersiveengineering:sheetmetal@8"
            ]
        },
        {
            "x": 21,
            "y": -1,
            "z": -3,
            "elements": [
                "immersiveengineering:sheetmetal@8"
            ]
        },
        {
            "x": 20,
            "y": -1,
            "z": -3,
            "elements": [
                "immersiveengineering:sheetmetal@8"
            ]
        },
        {
            "x": 19,
            "y": -1,
            "z": -3,
            "elements": [
                "immersiveengineering:sheetmetal@8"
            ]
        },
        {
            "x": 18,
            "y": -1,
            "z": -3,
            "elements": [
                "immersiveengineering:sheetmetal@8"
            ]
        },
        {
            "x": 17,
            "y": -1,
            "z": -3,
            "elements": [
                "immersiveengineering:sheetmetal@8"
            ]
        },
        {
            "x": 16,
            "y": -1,
            "z": -3,
            "elements": [
                "immersiveengineering:sheetmetal@8"
            ]
        },
        {
            "x": 15,
            "y": -1,
            "z": -3,
            "nbt": {"conveyorBeltSubtypeNBT":{"cover":{"id":"minecraft:air","Count":"1b","Damage":"0s"},"dyeColour":"-1","direction":"0"},"facing":"3","conveyorBeltSubtype":"immersiveengineering:covered","id":"immersiveengineering:conveyorbelt"},
            "elements": [
                "immersiveengineering:conveyor@0"
            ]
        },
        {
            "x": 14,
            "y": -1,
            "z": -3,
            "elements": [
                "immersiveengineering:sheetmetal@8"
            ]
        },
        {
            "x": 13,
            "y": -1,
            "z": -3,
            "elements": [
                "immersiveengineering:sheetmetal@8"
            ]
        },
        {
            "x": 12,
            "y": -1,
            "z": -3,
            "elements": [
                "immersiveengineering:sheetmetal@8"
            ]
        },
        {
            "x": 11,
            "y": -1,
            "z": -3,
            "elements": [
                "immersiveengineering:sheetmetal@8"
            ]
        },
        {
            "x": 10,
            "y": -1,
            "z": -3,
            "elements": [
                "immersiveengineering:sheetmetal@8"
            ]
        },
        {
            "x": -10,
            "y": 1,
            "z": 3,
            "elements": [
                "immersiveengineering:metal_multiblock"
            ]
        },
        {
            "x": 9,
            "y": -1,
            "z": -3,
            "elements": [
                "immersiveengineering:sheetmetal@8"
            ]
        },
        {
            "x": -9,
            "y": 1,
            "z": 3,
            "elements": [
                "immersiveengineering:metal_multiblock"
            ]
        },
        {
            "x": 8,
            "y": -1,
            "z": -3,
            "elements": [
                "immersiveengineering:sheetmetal@8"
            ]
        },
        {
            "x": 7,
            "y": -1,
            "z": -3,
            "elements": [
                "immersiveengineering:sheetmetal@8"
            ]
        },
        {
            "x": -8,
            "y": 1,
            "z": 3,
            "elements": [
                "immersiveengineering:metal_multiblock"
            ]
        },
        {
            "x": 5,
            "y": -1,
            "z": -3,
            "nbt": {"id":"immersiveengineering:ieslab","slabType":"0"},
            "elements": [
                "immersiveengineering:sheetmetal_slab@8"
            ]
        },
        {
            "x": 4,
            "y": -1,
            "z": -3,
            "nbt": {"busSize":"1","casingColor":"16730368","id":"minecraft:tileiteminputbus"},
            "elements": [
                "modularmachinery:blockinputbus@1"
            ]
        },
        {
            "x": 3,
            "y": -1,
            "z": -3,
            "nbt": {"id":"immersiveengineering:ieslab","slabType":"0"},
            "elements": [
                "immersiveengineering:sheetmetal_slab@8"
            ]
        },
        {
            "x": 4,
            "y": 3,
            "z": -1,
            "nbt": {"conveyorBeltSubtypeNBT":{"dyeColour":"-1","direction":"0"},"facing":"2","conveyorBeltSubtype":"immersiveengineering:conveyor","id":"immersiveengineering:conveyorbelt"},
            "elements": [
                "immersiveengineering:conveyor@0"
            ]
        },
        {
            "x": -10,
            "y": 2,
            "z": 3,
            "elements": [
                "immersiveengineering:metal_multiblock"
            ]
        },
        {
            "x": -9,
            "y": 2,
            "z": 3,
            "elements": [
                "immersiveengineering:metal_multiblock"
            ]
        },
        {
            "x": -8,
            "y": 2,
            "z": 3,
            "elements": [
                "immersiveengineering:metal_multiblock"
            ]
        },
        {
            "x": 21,
            "y": 4,
            "z": -16,
            "nbt": {"conveyorBeltSubtypeNBT":{"dyeColour":"-1","direction":"0"},"facing":"2","conveyorBeltSubtype":"immersiveengineering:conveyor","id":"immersiveengineering:conveyorbelt"},
            "elements": [
                "immersiveengineering:conveyor@0"
            ]
        },
        {
            "x": 4,
            "y": 2,
            "z": -1,
            "elements": [
                "immersiveengineering:metal_decoration1@1"
            ]
        },
        {
            "x": 15,
            "y": 4,
            "z": -16,
            "nbt": {"conveyorBeltSubtypeNBT":{"dyeColour":"-1","direction":"0"},"facing":"2","conveyorBeltSubtype":"immersiveengineering:conveyor","id":"immersiveengineering:conveyorbelt"},
            "elements": [
                "immersiveengineering:conveyor@0"
            ]
        },
        {
            "x": 14,
            "y": 4,
            "z": -16,
            "nbt": {"conveyorBeltSubtypeNBT":{"dyeColour":"-1","direction":"0"},"facing":"5","conveyorBeltSubtype":"immersiveengineering:conveyor","id":"immersiveengineering:conveyorbelt"},
            "elements": [
                "immersiveengineering:conveyor@0"
            ]
        },
        {
            "x": 13,
            "y": 4,
            "z": -16,
            "nbt": {"conveyorBeltSubtypeNBT":{"dyeColour":"-1","direction":"0"},"facing":"5","conveyorBeltSubtype":"immersiveengineering:conveyor","id":"immersiveengineering:conveyorbelt"},
            "elements": [
                "immersiveengineering:conveyor@0"
            ]
        },
        {
            "x": 12,
            "y": 4,
            "z": -16,
            "nbt": {"conveyorBeltSubtypeNBT":{"dyeColour":"-1","direction":"0"},"facing":"5","conveyorBeltSubtype":"immersiveengineering:conveyor","id":"immersiveengineering:conveyorbelt"},
            "elements": [
                "immersiveengineering:conveyor@0"
            ]
        },
        {
            "x": 11,
            "y": 4,
            "z": -16,
            "nbt": {"conveyorBeltSubtypeNBT":{"dyeColour":"-1","direction":"0"},"facing":"5","conveyorBeltSubtype":"immersiveengineering:conveyor","id":"immersiveengineering:conveyorbelt"},
            "elements": [
                "immersiveengineering:conveyor@0"
            ]
        },
        {
            "x": 10,
            "y": 4,
            "z": -16,
            "nbt": {"conveyorBeltSubtypeNBT":{"dyeColour":"-1","direction":"0"},"facing":"5","conveyorBeltSubtype":"immersiveengineering:conveyor","id":"immersiveengineering:conveyorbelt"},
            "elements": [
                "immersiveengineering:conveyor@0"
            ]
        },
        {
            "x": 9,
            "y": 4,
            "z": -16,
            "nbt": {"conveyorBeltSubtypeNBT":{"dyeColour":"-1","direction":"0"},"facing":"5","conveyorBeltSubtype":"immersiveengineering:conveyor","id":"immersiveengineering:conveyorbelt"},
            "elements": [
                "immersiveengineering:conveyor@0"
            ]
        },
        {
            "x": 8,
            "y": 4,
            "z": -16,
            "nbt": {"conveyorBeltSubtypeNBT":{"dyeColour":"-1","direction":"0"},"facing":"5","conveyorBeltSubtype":"immersiveengineering:conveyor","id":"immersiveengineering:conveyorbelt"},
            "elements": [
                "immersiveengineering:conveyor@0"
            ]
        },
        {
            "x": 7,
            "y": 4,
            "z": -16,
            "nbt": {"conveyorBeltSubtypeNBT":{"dyeColour":"-1","direction":"0"},"facing":"5","conveyorBeltSubtype":"immersiveengineering:conveyor","id":"immersiveengineering:conveyorbelt"},
            "elements": [
                "immersiveengineering:conveyor@0"
            ]
        },
        {
            "x": 6,
            "y": 4,
            "z": -16,
            "nbt": {"conveyorBeltSubtypeNBT":{"dyeColour":"-1","direction":"0"},"facing":"5","conveyorBeltSubtype":"immersiveengineering:conveyor","id":"immersiveengineering:conveyorbelt"},
            "elements": [
                "immersiveengineering:conveyor@0"
            ]
        },
        {
            "x": 5,
            "y": 4,
            "z": -16,
            "nbt": {"conveyorBeltSubtypeNBT":{"dyeColour":"-1","direction":"0"},"facing":"5","conveyorBeltSubtype":"immersiveengineering:conveyor","id":"immersiveengineering:conveyorbelt"},
            "elements": [
                "immersiveengineering:conveyor@0"
            ]
        },
        {
            "x": -10,
            "y": 3,
            "z": 3,
            "elements": [
                "immersiveengineering:metal_multiblock"
            ]
        },
        {
            "x": -9,
            "y": 3,
            "z": 3,
            "elements": [
                "immersiveengineering:metal_multiblock"
            ]
        },
        {
            "x": -10,
            "y": -1,
            "z": 1,
            "elements": [
                "immersiveengineering:metal_multiblock"
            ]
        },
        {
            "x": -8,
            "y": 3,
            "z": 3,
            "elements": [
                "immersiveengineering:metal_multiblock"
            ]
        },
        {
            "x": -8,
            "y": -1,
            "z": 1,
            "elements": [
                "immersiveengineering:metal_multiblock"
            ]
        },
        {
            "x": 21,
            "y": -1,
            "z": -18,
            "nbt": {"conveyorBeltSubtypeNBT":{"cover":{"id":"minecraft:air","Count":"1b","Damage":"0s"},"dyeColour":"-1","direction":"0"},"facing":"3","conveyorBeltSubtype":"immersiveengineering:covered","id":"immersiveengineering:conveyorbelt"},
            "elements": [
                "immersiveengineering:conveyor@0"
            ]
        },
        {
            "x": 21,
            "y": 3,
            "z": -16,
            "elements": [
                "immersiveengineering:metal_decoration1@1"
            ]
        },
        {
            "x": 15,
            "y": -1,
            "z": -18,
            "nbt": {"conveyorBeltSubtypeNBT":{"cover":{"id":"minecraft:air","Count":"1b","Damage":"0s"},"dyeColour":"-1","direction":"0"},"facing":"3","conveyorBeltSubtype":"immersiveengineering:covered","id":"immersiveengineering:conveyorbelt"},
            "elements": [
                "immersiveengineering:conveyor@0"
            ]
        },
        {
            "x": 0,
            "y": -1,
            "z": 1,
            "elements": [
                "immersiveengineering:metal_decoration1@0"
            ]
        },
        {
            "x": 15,
            "y": 3,
            "z": -16,
            "elements": [
                "immersiveengineering:metal_decoration1@1"
            ]
        },
        {
            "x": 14,
            "y": 3,
            "z": -16,
            "elements": [
                "immersiveengineering:metal_decoration1@1"
            ]
        },
        {
            "x": 13,
            "y": 3,
            "z": -16,
            "elements": [
                "immersiveengineering:metal_decoration1@1"
            ]
        },
        {
            "x": 12,
            "y": 3,
            "z": -16,
            "elements": [
                "immersiveengineering:metal_decoration1@1"
            ]
        },
        {
            "x": 4,
            "y": -1,
            "z": 1,
            "nbt": {"conveyorBeltSubtypeNBT":{"transferTickrate":"8","extractDirection":"2","dyeColour":"-1","direction":"0"},"facing":"3","conveyorBeltSubtype":"immersiveengineering:extract","id":"immersiveengineering:conveyorbelt"},
            "elements": [
                "immersiveengineering:conveyor@0"
            ]
        },
        {
            "x": 9,
            "y": -1,
            "z": -18,
            "nbt": {"conveyorBeltSubtypeNBT":{"cover":{"id":"minecraft:air","Count":"1b","Damage":"0s"},"dyeColour":"-1","direction":"0"},"facing":"3","conveyorBeltSubtype":"immersiveengineering:covered","id":"immersiveengineering:conveyorbelt"},
            "elements": [
                "immersiveengineering:conveyor@0"
            ]
        },
        {
            "x": 11,
            "y": 3,
            "z": -16,
            "elements": [
                "immersiveengineering:metal_decoration1@1"
            ]
        },
        {
            "x": 10,
            "y": 3,
            "z": -16,
            "elements": [
                "immersiveengineering:metal_decoration1@1"
            ]
        },
        {
            "x": 9,
            "y": 3,
            "z": -16,
            "elements": [
                "immersiveengineering:metal_decoration1@1"
            ]
        },
        {
            "x": 8,
            "y": 3,
            "z": -16,
            "elements": [
                "immersiveengineering:metal_decoration1@1"
            ]
        },
        {
            "x": 7,
            "y": 3,
            "z": -16,
            "elements": [
                "immersiveengineering:metal_decoration1@1"
            ]
        },
        {
            "x": 6,
            "y": 3,
            "z": -16,
            "elements": [
                "immersiveengineering:metal_decoration1@1"
            ]
        },
        {
            "x": 5,
            "y": 3,
            "z": -16,
            "elements": [
                "immersiveengineering:metal_decoration1@1"
            ]
        },
        {
            "x": 4,
            "y": 3,
            "z": -16,
            "nbt": {"conveyorBeltSubtypeNBT":{"dyeColour":"-1","direction":"0"},"facing":"5","conveyorBeltSubtype":"immersiveengineering:vertical","id":"immersiveengineering:conveyorbelt"},
            "elements": [
                "immersiveengineering:conveyor@0"
            ]
        },
        {
            "x": 14,
            "y": -1,
            "z": 1,
            "elements": [
                "immersiveengineering:metal_decoration1@0"
            ]
        },
        {
            "x": 15,
            "y": -1,
            "z": 1,
            "elements": [
                "immersiveengineering:metal_decoration1@0"
            ]
        },
        {
            "x": 16,
            "y": -1,
            "z": 1,
            "elements": [
                "immersiveengineering:metal_decoration1@0"
            ]
        },
        {
            "x": -10,
            "y": 4,
            "z": 3,
            "elements": [
                "immersiveengineering:metal_multiblock"
            ]
        },
        {
            "x": -9,
            "y": 4,
            "z": 3,
            "elements": [
                "immersiveengineering:metal_multiblock"
            ]
        },
        {
            "x": -10,
            "y": 0,
            "z": 1,
            "elements": [
                "immersiveengineering:metal_multiblock"
            ]
        },
        {
            "x": -8,
            "y": 4,
            "z": 3,
            "elements": [
                "immersiveengineering:metal_multiblock"
            ]
        },
        {
            "x": -9,
            "y": 0,
            "z": 1,
            "elements": [
                "immersiveengineering:metal_multiblock"
            ]
        },
        {
            "x": -8,
            "y": 0,
            "z": 1,
            "elements": [
                "immersiveengineering:metal_multiblock"
            ]
        },
        {
            "x": 21,
            "y": 2,
            "z": -16,
            "elements": [
                "immersiveengineering:metal_decoration1@1"
            ]
        },
        {
            "x": 0,
            "y": 0,
            "z": 1,
            "elements": [
                "immersiveengineering:metal_decoration1@0"
            ]
        },
        {
            "x": 15,
            "y": 2,
            "z": -16,
            "elements": [
                "immersiveengineering:metal_decoration1@1"
            ]
        },
        {
            "x": 9,
            "y": 2,
            "z": -16,
            "elements": [
                "immersiveengineering:metal_decoration1@1"
            ]
        },
        {
            "x": 5,
            "y": 2,
            "z": -16,
            "elements": [
                "immersiveengineering:metal_decoration1@1"
            ]
        },
        {
            "x": 4,
            "y": 2,
            "z": -16,
            "nbt": {"conveyorBeltSubtypeNBT":{"dyeColour":"-1","direction":"0"},"facing":"5","conveyorBeltSubtype":"immersiveengineering:vertical","id":"immersiveengineering:conveyorbelt"},
            "elements": [
                "immersiveengineering:conveyor@0"
            ]
        },
        {
            "x": 16,
            "y": -1,
            "z": -1,
            "elements": [
                "immersiveengineering:metal_decoration1@0"
            ]
        },
        {
            "x": 15,
            "y": -1,
            "z": -1,
            "nbt": {"conveyorBeltSubtypeNBT":{"dyeColour":"-1","direction":"0"},"facing":"3","conveyorBeltSubtype":"immersiveengineering:conveyor","id":"immersiveengineering:conveyorbelt"},
            "elements": [
                "immersiveengineering:conveyor@0"
            ]
        },
        {
            "x": 14,
            "y": -1,
            "z": -1,
            "elements": [
                "immersiveengineering:metal_decoration1@0"
            ]
        },
        {
            "x": -10,
            "y": 5,
            "z": 3,
            "elements": [
                "immersiveengineering:metal_multiblock"
            ]
        },
        {
            "x": -9,
            "y": 5,
            "z": 3,
            "elements": [
                "immersiveengineering:metal_multiblock"
            ]
        },
        {
            "x": -8,
            "y": 5,
            "z": 3,
            "elements": [
                "immersiveengineering:metal_multiblock"
            ]
        },
        {
            "x": -10,
            "y": 1,
            "z": 1,
            "elements": [
                "immersiveengineering:metal_multiblock"
            ]
        },
        {
            "x": -9,
            "y": 1,
            "z": 1,
            "elements": [
                "immersiveengineering:metal_multiblock"
            ]
        },
        {
            "x": -8,
            "y": 1,
            "z": 1,
            "elements": [
                "immersiveengineering:metal_multiblock"
            ]
        },
        {
            "x": 5,
            "y": -1,
            "z": -1,
            "nbt": {"id":"immersiveengineering:ieslab","slabType":"0"},
            "elements": [
                "immersiveengineering:sheetmetal_slab@8"
            ]
        },
        {
            "x": 21,
            "y": 1,
            "z": -16,
            "elements": [
                "immersiveengineering:metal_decoration1@1"
            ]
        },
        {
            "x": 4,
            "y": -1,
            "z": -1,
            "nbt": {"casingColor":"16730368","id":"minecraft:tilecolorablemachinecomponent"},
            "elements": [
                "modularmachinery:blockcasing@0"
            ]
        },
        {
            "x": 3,
            "y": -1,
            "z": -1,
            "nbt": {"id":"immersiveengineering:ieslab","slabType":"0"},
            "elements": [
                "immersiveengineering:sheetmetal_slab@8"
            ]
        },
        {
            "x": 0,
            "y": 1,
            "z": 1,
            "elements": [
                "immersiveengineering:metal_decoration1@0"
            ]
        },
        {
            "x": 15,
            "y": 1,
            "z": -16,
            "elements": [
                "immersiveengineering:metal_decoration1@1"
            ]
        },
        {
            "x": 9,
            "y": 1,
            "z": -16,
            "elements": [
                "immersiveengineering:metal_decoration1@1"
            ]
        },
        {
            "x": 5,
            "y": 1,
            "z": -16,
            "elements": [
                "immersiveengineering:metal_decoration1@1"
            ]
        },
        {
            "x": 4,
            "y": 1,
            "z": -16,
            "nbt": {"conveyorBeltSubtypeNBT":{"dyeColour":"-1","direction":"0"},"facing":"5","conveyorBeltSubtype":"immersiveengineering:vertical","id":"immersiveengineering:conveyorbelt"},
            "elements": [
                "immersiveengineering:conveyor@0"
            ]
        },
        {
            "x": -10,
            "y": 2,
            "z": 1,
            "elements": [
                "immersiveengineering:metal_multiblock"
            ]
        },
        {
            "x": -9,
            "y": 2,
            "z": 1,
            "elements": [
                "immersiveengineering:metal_multiblock"
            ]
        },
        {
            "x": -8,
            "y": 2,
            "z": 1,
            "elements": [
                "immersiveengineering:metal_multiblock"
            ]
        },
        {
            "x": 21,
            "y": 0,
            "z": -16,
            "elements": [
                "immersiveengineering:metal_decoration1@1"
            ]
        },
        {
            "x": 21,
            "y": 4,
            "z": -14,
            "nbt": {"conveyorBeltSubtypeNBT":{"dyeColour":"-1","direction":"0"},"facing":"2","conveyorBeltSubtype":"immersiveengineering:conveyor","id":"immersiveengineering:conveyorbelt"},
            "elements": [
                "immersiveengineering:conveyor@0"
            ]
        },
        {
            "x": 15,
            "y": 0,
            "z": -16,
            "elements": [
                "immersiveengineering:metal_decoration1@1"
            ]
        },
        {
            "x": 9,
            "y": 0,
            "z": -16,
            "elements": [
                "immersiveengineering:metal_decoration1@1"
            ]
        },
        {
            "x": 5,
            "y": 0,
            "z": -16,
            "elements": [
                "immersiveengineering:metal_decoration1@1"
            ]
        },
        {
            "x": 4,
            "y": 0,
            "z": -16,
            "nbt": {"conveyorBeltSubtypeNBT":{"dyeColour":"-1","direction":"0"},"facing":"5","conveyorBeltSubtype":"immersiveengineering:vertical","id":"immersiveengineering:conveyorbelt"},
            "elements": [
                "immersiveengineering:conveyor@0"
            ]
        },
        {
            "x": -10,
            "y": 3,
            "z": 1,
            "elements": [
                "immersiveengineering:metal_multiblock"
            ]
        },
        {
            "x": -9,
            "y": 3,
            "z": 1,
            "elements": [
                "immersiveengineering:metal_multiblock"
            ]
        },
        {
            "x": -8,
            "y": 3,
            "z": 1,
            "elements": [
                "immersiveengineering:metal_multiblock"
            ]
        },
        {
            "x": 21,
            "y": -1,
            "z": -16,
            "nbt": {"conveyorBeltSubtypeNBT":{"cover":{"id":"minecraft:air","Count":"1b","Damage":"0s"},"dyeColour":"-1","direction":"0"},"facing":"3","conveyorBeltSubtype":"immersiveengineering:covered","id":"immersiveengineering:conveyorbelt"},
            "elements": [
                "immersiveengineering:conveyor@0"
            ]
        },
        {
            "x": 21,
            "y": 3,
            "z": -14,
            "elements": [
                "immersiveengineering:metal_decoration1@1"
            ]
        },
        {
